Workbook

Sheet stats_2026
B1: Searched
A2: D | B2: Duplicates | C2: =countif(survey_paper_2026!$F$2:$F$164,A2) -> 0
A3: IR | B3: Invalid Record | C3: =countif(survey_paper_2026!$F$2:$F$164,A3) -> 32
A4: ST | B4: Screened Out by Title | C4: =countif(survey_paper_2026!$F$2:$F$164,A4) -> 4
A5: SA | B5: Screened Out by Abstract | C5: =countif(survey_paper_2026!$F$2:$F$164,A5) -> 22
A6: SF | B6: Screened Out by full text | C6: =countif(survey_paper_2026!$F$2:$F$164,A6) -> 3
A7: P | B7: Passed | C7: =countif(survey_paper_2026!$F$2:$F$164,A7) -> 92
A8: RT | B8: Retrected | C8: =countif(survey_paper_2026!$F$2:$F$164,A8) -> 1
A9: NA | B9: Not Available | C9: =countif(survey_paper_2026!$F$2:$F$164,A9) -> 8
C10: =SUM(C2:C9) -> 162 | D10: of 162
A12: Y | B12: In Paper | C12: =COUNTIF(survey_paper_2026!G2:G163,A12) -> 92
C13: =C7-C12 -> 0

Sheet survey_paper_2026
A1: Authors | B1: Title | C1: Year | D1: Cited by | E1: Link | F1: Status | G1: In Paper | H1: Overlap | I1: Abstract
A2: Li, Y.; Mercan, E.; Knezevitch, S.; Elmore, J.G.; Shapiro, L.G. | B2: Efficient and Accurate Mitosis Detection A Lightweight RCNN Approach | C2: 2018 | D2: 22 | E2: https://www.scopus.com/inward/record.uri?eid=2-s2.0-85052023801&doi=10.5220%2F0006550700690077&partnerID=40&md5=a8da73e482f17fc0f87fdf61f24d2a82 | F2: P | G2: Y | H2: =countif(Survey!$E$2:$E$57,E2) -> 0 | I2: The analysis of breast cancer images includes the detection of mitotic figures whose counting is important in the grading of invasive breast cancer. Mitotic figures are difficult to find in the very large whole slide images, as they may look only slightly different from normal nuclei. In the last few years, several convolutional neural network (CNN) systems have been developed for mitosis detection that are able to beat conventional, feature-based approaches. However, these networks contain many layers and many neurons per layer, so both training and actual classification require powerful computers with GPUs. In this paper, we describe a new lightweight region-based CNN methodology we have developed that is able to run on standard machines with only a CPU and can achieve accuracy measures that are almost as good as the best CNN-based system so far in a fraction of the time, when both are run on CPUs. Our system, which includes a feature-based region extractor plus two CNN stages, is tested on the ICPR 2012 and ICPR 2014 datasets, and results are given for accuracy and timing. © © 2018 by SCITEPRESS – Science and Technology Publications, Lda. All rights reserved
A3: Oliveira, H.S.; Teixeira, J.F.; Oliveira, H.P. | B3: Lightweight deep learning pipeline for detection, segmentation and classification of breast cancer anomalies | C3: 2019 | D3: 10 | E3: https://www.scopus.com/inward/record.uri?eid=2-s2.0-85072901730&doi=10.1007%2F978-3-030-30645-8_64&partnerID=40&md5=9f19b44d7075729e35846cda32bbe51b | F3: P | G3: Y | H3: =countif(Survey!$E$2:$E$57,E3) -> 0 | I3: The small amount of public available medical images hinders the use of deep learning techniques for mammogram automatic diagnosis. Deep learning methods require large annotated training sets to be effective, however medical datasets are costly to obtain and suffer from large variability. In this work, a lightweight deep learning pipeline to detect, segment and classify anomalies in mammogram images is presented. First, data augmentation using the ground-truth annotation is performed and used by a cascade segmentation and classification methods. Results are obtained using the INbreast public database in the context of lesion detection and BI-RADS classification. Moreover, a pre-trained Convolutional Neural Network using ResNet50 is modified to generate the lesion regions proposals followed by a false positive reduction and contour refinement stages while a pre-trained VGG16 network is fine-tuned to classify mammograms. The detection and segmentation stage results show that the cascade configuration achieves a DICE of 0.83 without massive training while the multi-class classification exhibits an MAE of 0.58 with data augmentation. © Springer Nature Switzerland AG 2019.
A4: Elbashir, M.K.; Ezz, M.; Mohammed, M.; Saloum, S.S. | B4: Lightweight convolutional neural network for breast cancer classification using RNA-Seq gene expression data | C4: 2019 | D4: 74 | E4: https://www.scopus.com/inward/record.uri?eid=2-s2.0-85077964825&doi=10.1109%2FACCESS.2019.2960722&partnerID=40&md5=67da4ac6fe40be475c395aa316fdb2fe | F4: P | G4: Y | H4: =countif(Survey!$E$2:$E$57,E4) -> 0 | I4: Gene expressions are considered among the most used features in cancer classification. The available gene expression data has a small number of samples and a relatively big number of dimensions, and that makes it not suitable for deep Convolutional Neural Networks (CNN) architectures, which exhibit state-of-the-art performance in many fields. In this paper, we propose a lightweight CNN architecture for breast cancer classification using gene expression data downloaded from Pan-Cancer Atlas using 'Illumina HiSeq' platform. The downloaded gene expression data is preprocessed and then transformed into 2D-images. We started the preprocessing by removing the outlier samples, which are determined based on the Array-Array Intensity Correlation (AAIC), which defines a symmetric square matrix of Spearman correlation. Then we applied a normalization process on the gene expression data to ensure that we can infer the expression level from it correctly and avoid biases in the expression measures. Finally, filtering is applied on the data. Model selection or a parameters search strategy is conducted to choose the values of the CNN hyper-parameters that give optimal performance. Our experiments show that our proposed method achieves an accuracy of 98.76%, which is the highest compared to other competing methods. © 2013 IEEE.
A5: Abdelli, A.; Saouli, R.; Djemal, K.; Youkana, I. | B5: Combined Datasets for Breast Cancer Grading Based on Multi-CNN Architectures | C5: 2020 | D5: 11 | E5: https://www.scopus.com/inward/record.uri?eid=2-s2.0-85099272967&doi=10.1109%2FIPTA50016.2020.9286653&partnerID=40&md5=2fbf0269703a803895ed30d3b9deaa9e | F5: P | G5: Y | H5: =countif(Survey!$E$2:$E$57,E5) -> 0 | I5: Breast cancer is the most leading cancer among women. Usually, pathologists have to examine the histological image slides through the whole slides tissues in different magnifications, to extract the tumor malignancy then the tumor grade. These image's interpretation is one of the time and effort consuming task to define an accurate diagnosis. Consequently, Computer-Aided Diagnosis (CAD) systems are highly demanded. However, the histological images have pervasive variability, which is a big challenge due to the variation of tissue textures and which is hard to be interpreted by the computer. For this, deep learning algorithms have been promised architectures for complex objects, but the problem of the low resource of datasets is still yet a constraint to build an efficient medical system for image classification. In this work, we propose a solution based on combining two different datasets for breast cancer grade detection. Our proposed method is about adding a new class (grade 0) to the three known classes of breast cancer grades, which make our model detect both the malignancy and the grade of the breast tumors. Furthermore, both datasets images have the same magnification factor which helps our models in avoiding overfitting problems. Our models are trained using two different convolutional neural network architectures, the ResNet50 and the MobileNet for comparing between a lightweight and heavyweight architectures. The obtained results show the best accuracy in the state-of-the-art. © 2020 IEEE.
A6: Zhang, X.; Lin, X.; Zhang, Z.; Dong, L.; Sun, X.; Sun, D.; Yuan, K. | B6: Artificial Intelligence Medical Ultrasound Equipment: Application of Breast Lesions Detection | C6: 2020 | D6: 25 | E6: https://www.scopus.com/inward/record.uri?eid=2-s2.0-85086567155&doi=10.1177%2F0161734620928453&partnerID=40&md5=cf1013a4a61fe2c418e678c32e1a8ca7 | F6: P | G6: Y | H6: =countif(Survey!$E$2:$E$57,E6) -> 0 | I6: Breast cancer ranks first among cancers affecting women’s health. Our work aims to realize the intelligence of the medical ultrasound equipment with limited computational capability, which is used for the assistant detection of breast lesions. We embed the high-computational deep learning algorithm into the medical ultrasound equipment with limited computational capability by two techniques: (1) lightweight neural network: considering the limited computational capability of ultrasound equipment, a lightweight neural network is designed, which greatly reduces the amount of calculation. And we use the technique of knowledge distillation to train the low-precision network helped with the high-precision network; (2) asynchronous calculations: consider four frames of ultrasound images as a group; the image of the first frame of each group is used as the input of the network, and the result is respectively fused with the images of the fourth to seventh frames. An amount of computation of 30 GFLO/frame is required for the proposed lightweight neural network, about 1/6 of that of the large high-precision network. After trained from scratch using the knowledge distillation technique, the detection performance of the lightweight neural network (sensitivity = 89.25%, specificity = 96.33%, the average precision [AP] = 0.85) is close to that of the high-precision network (sensitivity = 98.3%, specificity = 88.33%, AP = 0.91). By asynchronous calculation, we achieve real-time automatic detection of 24 fps (frames per second) on the ultrasound equipment. Our work proposes a method to realize the intelligence of the low-computation-power ultrasonic equipment, and successfully achieves the real-time assistant detection of breast lesions. The significance of the study is as follows: (1) The proposed method is of practical significance in assisting doctors to detect breast lesions; (2) our method provides some practical and theoretical support for the development and engineering of intelligent equipment based on artificial intelligence algorithms. © The Author(s) 2020.
A7: Laxmisagar, H.S.; Hanumantharaju, M.C. | B7: Design of an Efficient Deep Neural Network for Multi-level Classification of Breast Cancer Histology Images | C7: 2021 | D7: 4 | E7: https://www.scopus.com/inward/record.uri?eid=2-s2.0-85092725831&doi=10.1007%2F978-981-15-5566-4_40&partnerID=40&md5=6e196fdf9fa7acea758ac1273180ebe7 | F7: P | G7: Y | H7: =countif(Survey!$E$2:$E$57,E7) -> 0 | I7: Breast cancer is the second most prominent cause of death among women, and it is a major health problem across the world over the past many years. In this work, four hundred different biopsy images were collected from the Bio-imaging 2018 breast histology classification challenge by participating Grand Challenge on breast cancer histology images (BACH) for multiclass breast cancer histology image classification using deep learning technique. Computer-aided detection or diagnosis (CAD) system plays an important role in the detection and to increase death survival rate of women suffering from breast cancer, which can decrease death rate among women. The main purpose of this paper is to develop a CAD system which can be used to detect whether the input biopsy image fits one of the four different classes like benign, in situ, Invasive and Malignant. We have incorporated an efficient lightweight neural network such as MobileNet2.10ex instead of normal convolution neural network for feature extraction and at top a fully connected deep neural network is designed to do classification among different classes. The confusion matrix is developed in order to draw the model accuracy of both techniques. It is observed that MobleNet2.10ex is giving about 88.92 % training accuracy at 257 epochs and the corresponding loss value is 0.2249. In order to progress the performance during pre-processing, a staining technique was used to remove staining from a digital scan of histology microscopic image of fine-needle aspirate (FNA) slides and feature invariant approach such as data augmentation technique was used to rotate each image in pipeline about the axis 45° apart three times in order to increase dataset and prediction accuracy. The model was trained till 280 epochs to evaluate training and validation accuracy using Google Colab having strong GPU 2496 CUDA cores, 12 GB GDDR5 VRAM and 12.6 GB RAM. © 2021, Springer Nature Singapore Pte Ltd.
A8: Zahir, S.; Amir, A.; Zahri, N.A.H.; Ang, W.C. | B8: Applying the Deep Learning Model on an IoT Board for Breast Cancer Detection based on Histopathological Images | C8: 2021 | D8: 8 | E8: https://www.scopus.com/inward/record.uri?eid=2-s2.0-85102409958&doi=10.1088%2F1742-6596%2F1755%2F1%2F012026&partnerID=40&md5=3342ebdea94a79259464e7bf1b1f420c | F8: P | G8: Y | H8: =countif(Survey!$E$2:$E$57,E8) -> 0 | I8: In breast cancer diagnosis, pathologists evaluate microscopic images of tissue samples to determine if it is benign or malignant. The manual examination process could result in delayed diagnosis, which leads to late cancer treatment and can risk lives. In this paper, we proposed an automated, low-cost, and portable breast cancer detection based on histopathological images by using deep learning. The deep learning models were designed by using the Convolutional Neural Network (CNN). This paper compares the performance of the CNN model by using transfer learning utilizing a pre-trained model (VGG16) and the performance of a CNN model without transfer learning. The result shows that transfer learning provides a good base for classification of histopathological images. The model was successfully deployed on a Raspberry Pi, which demonstrates the model efficiency to run on a lightweight and portable processor. © 2021 Published under licence by IOP Publishing Ltd.
A9: Laxmisagar, H.S.; Hanumantharaju, M.C. | B9: Detection of Breast Cancer with Lightweight Deep Neural Networks for Histology Image Classification | C9: 2022 | D9: 13 | E9: https://www.scopus.com/inward/record.uri?eid=2-s2.0-85138239272&doi=10.1615%2FCritRevBiomedEng.2022043417&partnerID=40&md5=85ac07e56c86bb4fcdaee9cc247787e9 | F9: P | G9: Y | H9: =countif(Survey!$E$2:$E$57,E9) -> 0 | I9: Many researchers have developed computer-assisted diagnostic (CAD) methods to diagnose breast cancer using histopathology microscopic images. These techniques help to improve the accuracy of biopsy diagnosis with hematoxylin and eosin-stained images. On the other hand, most CAD systems usually rely on inefficient and time-consuming manual feature extraction methods. Using a deep learning (DL) model with convolutional layers, we present a method to extract the most useful pictorial information for breast cancer classification. Breast biopsy images stained with hematoxylin and eosin can be categorized into four groups namely benign lesions, normal tissue, carcinoma in situ, and invasive carcinoma. To correctly classify different types of breast cancer, it is important to classify histopathological images accurately. The MobileNet architecture model is used to obtain high accuracy with less resource utilization. The proposed model is fast, inexpensive, and safe due to which it is suitable for the detection of breast cancer at an early stage. This lightweight deep neural network can be accelerated using field-programmable gate arrays for the detection of breast cancer. DL has been implemented to successfully classify breast cancer. The model uses categorical cross-entropy to learn to give the correct class a high probability and other classes a low probability. It is used in the classification stage of the convolutional neural network (CNN) after the clustering stage, thereby improving the performance of the proposed system. To measure training and validation accuracy, the model was trained on Google Colab for 280 epochs with a powerful GPU with 2496 CUDA cores, 12 GB GDDR5 VRAM, and 12.6 GB RAM. Our results demonstrate that deep CNN with a chi-square test has improved the accuracy of histopathological image classification of breast cancer by greater than 11% compared with other state-of-the-art methods. © 2022 by Begell House, Inc.
A10: Kim, S.; Yoon, K. | B10: Deep and lightweight neural network for histopathological image classification | C10: 2022 | D10: 3 | E10: https://www.scopus.com/inward/record.uri?eid=2-s2.0-85139222990&doi=10.13052%2Fjmm1550-4646.18619&partnerID=40&md5=da2a1aa1668572887810f27b242c2214 | F10: P | G10: Y | H10: =countif(Survey!$E$2:$E$57,E10) -> 0 | I10: Breast cancer is a fatal disease affecting women, and early detection and proper treatment are crucial. Classifying medical images correctly is the first and most important step in the cancer diagnosis stage. Deep learning-based classification methods in various domains demonstrate advances in accuracy. However, as deep learning improves, the layers of neural networks get deeper, raising challenges, such as overfitting and gradient vanishing. For instance, a medical image is simpler than an ordinary one, making it vulnerable to overfitting issues. We present breast histopathological classification methods with two deep neural networks, Xception and LightXception with aid of voting schemes over split images. Most deep neural networks classify thousands classes of images, but the breast histopathological image classes are far fewer than those of other image classification tasks. Because the BreakHis dataset is relatively simpler than typical image datasets, such as ImageNet, applying the conventional highly deep neural networks may suffer from the aforementioned overfitting or gradient vanishing problems. Additionally, highly deep neural networks require more resources, leading to high computational costs. Consequently, we propose a new network; LightXception by cutting off layers at the bottom of the Xception network and reducing the number of channels of convolution filters. LightXception has only about 35% of parameters compared to those of the original Xception network with minimal expense on performance. Based on images with 100X magnification factor, the performance comparisons for Xception vs. LightXception are 97.42% vs. 97.31% on classification accuracy, 97.42% vs. 97.42% on recall, and 99.26% vs. 98.67% of precision. © 2022 River Publishers. All rights reserved.
A11: Huang, J.; Mei, L.; Long, M.; Liu, Y.; Sun, W.; Li, X.; Shen, H.; Zhou, F.; Ruan, X.; Wang, D.; Wang, S.; Hu, T.; Lei, C. | B11: BM-Net: CNN-Based MobileNet-V3 and Bilinear Structure for Breast Cancer Detection in Whole Slide Images | C11: 2022 | D11: 30 | E11: https://www.scopus.com/inward/record.uri?eid=2-s2.0-85132930127&doi=10.3390%2Fbioengineering9060261&partnerID=40&md5=2061b61f9c49957ac6fa8f9427c5bb70 | F11: P | G11: Y | H11: =countif(Survey!$E$2:$E$57,E11) -> 0 | I11: Breast cancer is one of the most common types of cancer and is the leading cause of cancer-related death. Diagnosis of breast cancer is based on the evaluation of pathology slides. In the era of digital pathology, these slides can be converted into digital whole slide images (WSIs) for further analysis. However, due to their sheer size, digital WSIs diagnoses are time consuming and challenging. In this study, we present a lightweight architecture that consists of a bilinear structure and MobileNet-V3 network, bilinear MobileNet-V3 (BM-Net), to analyze breast cancer WSIs. We utilized the WSI dataset from the ICIAR2018 Grand Challenge on Breast Cancer Histology Images (BACH) competition, which contains four classes: normal, benign, in situ carcinoma, and invasive carcinoma. We adopted data augmentation techniques to increase diversity and utilized focal loss to remove class imbalance. We achieved high performance, with 0.88 accuracy in patch classification and an average 0.71 score, which surpassed state-of-the-art models. Our BM-Net shows great potential in detecting cancer in WSIs and is a promising clinical tool. © 2022 by the authors. Licensee MDPI, Basel, Switzerland.
A12: Garg, S.; Singh, P. | B12: Transfer Learning Based Lightweight Ensemble Model for Imbalanced Breast Cancer Classification | C12: 2023 | D12: 31 | E12: https://www.scopus.com/inward/record.uri?eid=2-s2.0-85132534568&doi=10.1109%2FTCBB.2022.3174091&partnerID=40&md5=e4a812f8afb738e87a9fcc87c306ca63 | F12: P | G12: Y | H12: =countif(Survey!$E$2:$E$57,E12) -> 0 | I12: Automated classification of breast cancer can often save lives, as manual detection is usually time-consuming expensive. Since the last decade, deep learning techniques have been most widely used for the automatic classification of breast cancer using histopathology images. This paper has performed the binary and multi-class classification of breast cancer using a transfer learning-based ensemble model. To analyze the correctness and reliability of the proposed model, we have used an imbalance IDC dataset, an imbalance BreakHis dataset in the binary class scenario, and a balanced BACH dataset for the multi-class classification. A lightweight shallow CNN model with batch normalization technology to accelerate convergence is aggregated with lightweight MobileNetV2 to improve learning and adaptability. The aggregation output is fed into a multilayer perceptron to complete the final classification task. The experimental study on all three datasets was performed and compared with the recent works. We have fine-tuned three different pre-trained models (ResNet50, InceptionV4, and MobilNetV2) and compared it with the proposed lightweight ensemble model in terms of execution time, number of parameters, model size, etc. In both the evaluation phases, it is seen that our model outperforms in all three datasets. © 2004-2012 IEEE.
A13: Patel, W.; Koyuncu, H.; Ganatara, A. | B13: Revolutionizing Cancer Diagnosis in IoMT with a Novel Lightweight Deep Learning Model for Histopathological Image Classification | C13: 2023 | D13: 1 | E13: https://www.scopus.com/inward/record.uri?eid=2-s2.0-85190115921&doi=10.1109%2FMoSICom59118.2023.10458800&partnerID=40&md5=fd257c5075ecd94fecf725ea2a1fdc8a | F13: P | G13: Y | H13: =countif(Survey!$E$2:$E$57,E13) -> 0 | I13: Our proposed solution for breast cancer diagnosis offers a highly reliable and efficient alternative to the traditional manual examination method. By utilizing deep learning models designed with Convolutional Neural Networks (CNN), We have created a breast cancer detection system that is automated, inexpensive, and easy to transport. A system that significantly reduces the risk of delayed diagnosis and saves lives. This approach relies on an integrated ultrasensitive micro-bio-heat sensor array structured as a 3x3 grid using Altium software. The array functions as an embedded system aiming for the early identification of breast cancer. Leveraging IoT advancements, this system can connect with a server through smartphones. This study demonstrates the effectiveness of switch getting to know in histopathological photo classification. This research assesses the effectiveness of CNN models, both with and without transfer learning. It uses a pre-Trained VGG16 model for image classification and demonstrates its successful implementation on a Raspberry Pi. This highlights its efficiency when running on a lightweight and portable processor. Our experimental results show that our system achieves an accuracy of 78% on the BreakHis database and can run on a Raspberry Pi device with minimal resources. © 2023 IEEE.
... A24: Modu, F.; Prasad, R.; Aliyu, F. | B24: Lightweight CNN for Resource-Constrained BCD System Using Knowledge Distillation | C24: 2025 | D24: 1 | E24: https://www.scopus.com/inward/record.uri?eid=2-s2.0-105002579088&doi=10.1109%2FACCESS.2025.3556517&partnerID=40&md5=af2b9a52232016fa55ca4b11e136a7d9 | F24: P | G24: Y | H24: =countif(Survey!$E$2:$E$57,E24) -> 0 | I24: Breast cancer (BC) remains a leading cause of mortality among women worldwide, with over two million new cases annually. Early detection improves survival rates significantly, yet resource limitations in low- and middle-income countries (LMICs) hinder access to advanced diagnostic tools. While deep learning (DL) models have shown high accuracy in breast cancer detection (BCD), their computational complexity and hardware requirements make them impractical for deployment on low-power devices. To address this, we propose a lightweight convolutional neural network (CNN) for BCD, leveraging knowledge distillation (KD) to transfer knowledge from a complex teacher model (TM) to a smaller student model (SM). Our approach achieves up to 99.3% accuracy, 100% precision, and 99% recall while reducing the number of trainable parameters by 87% compared to conventional deep models. The proposed model successfully runs on a Raspberry Pi 4B with an inference time of 500 ms and memory usage of just 12% (of 8GB RAM), demonstrating its suitability for telemedicine and mobile diagnostics. Additionally, resource utilization experiments confirm that inference remains stable at 10% CPU usage and 40°C when using a heat sink and fan, ensuring sustained deployment. Future work will explore federated learning for decentralized training, integration of multimodal data for enhanced diagnosis, and cloud-based model updates using delay-tolerant networks (DTNs) for remote healthcare applications. © 2013 IEEE.
B25: 2013 4th International Conference on Material and Manufacturing Technology, ICMMT 2013 | C25: 2013 | D25: 0 | E25: https://www.scopus.com/inward/record.uri?eid=2-s2.0-84884785762&partnerID=40&md5=31e4db38afaa379c6aa0f56556b495bd | F25: IR | H25: =countif(Survey!$E$2:$E$57,E25) -> 0 | I25: The proceedings contain 251 papers. The special focus in this conference is on Materials Engineering and Technology, Mechanical Engineering, Design Technology and Engineering, Applied Thermodynamics, Mechatronics and Robotics, Modern Control, Automation and Reverse Engineering, Civil Engineering, Manufacturing and Industrial Engineering and Data Mining, Information Technologies and Networks. The topics include: Flexural strength of PLA/kenaf green composite; aging behavior of the polyether polyurethane films irradiated by UV; synthesis of Fe-Al<inf>2</inf>O<inf>3</inf> composite by high-frequency induction-heated combustion; self-propagating high-temperature synthesis of Fe-W(B, C) based composite; electrochromic performance of NiO films in alkaline medium; oxidation of oxide dispersion strengthened steels; optimization of parameters in fiber reinforced polyurethane composited reaction injection molding; study on the foaming behavior of PS-CO2 by using water or ethanol as Co-blowing agent; the metastable phase responsible for hardenig in an Al-Mg alloy aged at 473K; investigations of nanostructure and photoluminescence properties of nanoporous silicon; characterization of high density solid waste biopolymer foam; effect of applied current density on the electrodeposition of Ni on Ti substrate; morphology and mechanical properties of HDPE/bio-polymer as compounding materials; mechanical properties of UV irradiated bio polymer thin films doped with titanium dioxide; adhesive bonding strength and adhesive penetration of two malaysian medium hardwoods; research development of the laser surface modification to improve the corrosion-resistance of titanium and titanium alloys; research progress of the surface oxidation of titanium and its alloys; development status of laser clad cobalt-based alloy coatings; application of the high strength steel in the automobile; effect of crack length on mixed-mode cohesive fracture of the adhesively bonded joints; a case study on effect of feed rate on machinability of austempered ductile iron; grinding force research on nanostructured ceramic coatings; research on nano-ceramic coatings precision grinding; CO<inf>2</inf> laser cladding of mild steel using iron based powder and silicon carbide particles; acoustic study based on sustainable green polymer treated with H2O; dynamic response of FDM made ABS parts in different part orientations; scaling up process output of monomer reactor; characterization of rice straw ash and utilization in glass production; investigation on carbon fiber composites as architectural EMI shielding material; durability of traffic signs and retroreflective materials; performance study on scale inhibition of biodegradable water treatment agent; simulation of laser-induced thermoelastic behavior in metal plates; stress analysis and fatigue life estimation of bridge rubber bearing; optimization design of a framework for an infrared seeker; the higher order crack-tip field for reissners power FGMs spherical shell; A Z-map based approach for extracting the groove shape of impeller; an efficient diffusion model for a real-time gas diffusion simulation system; design and simulation on righting manipulator of the remote control in workover operations; lightweight design optimization of large-tonnage hydraulic press body structure; prediction of long-term properties of fiberglass pipe based on the shift factors method; nonlinear aerodynamics reduced-order model based on multi-input volterra series; positive solutions of a strongly coupled prey-predator system; algorithm and realization of wind power prediction system; an improved islanding detection method for photovoltaic grid-connected system; switch technology in intelligent substation; study on energy optimization of clutch based on energy design factor; a combination method for mid-long term power load simulation and prediction; study of dual-active series resonant DC-DC converter for high power applications; capacitor group zero-crossing switching control system design; research and design of air conditioning air flow test bench; mono pulse confocal microwave imaging in breast cancer detection; two-dimensional laser detection front end circuit and algorithm; detection of pilot-induced oscillation (PIO); real time web based monitoring and calibration system for diesel engine; a safety monitoring device for firefighters based on wireless localization algorithm; garlic cutting umbilical based on image processing and GUI; clustering based on a novel density estimation method; analysis based on the remote sensing image of harbin urban heat island effect; the research on multiscale image fusion based on the dualtree complex wavelet; gesture recognition for briefing application; method on 3D dense point cloud recovery of geographical scene; implementation of unitary music algorithm using Xilinx system generator; sound source localization based on microphone uniform linear array; method of harmonic detection based on the wavelet transform; research and simulation of image histogram matching; based on HMM intonation prosody prediction of Tibetan TTS; the application of CRI method in fuzzy reasoning; fuzzy recognition intelligent system based on cash character; the perception system of external world for robot; a robot simulation system for self-location by using field visual information; sound analysis and synthesis for audio simulation system of flight simulator; research on the vision processing of space robot's tracking camera; the design of servo system for azimuth of directional antenna based on PMSM; application of sliding mode cascade controller in AC servo system; research on the detection unit and control system of CNC cool frame bender; semistability of nonlinear control systems; the study of DC motor position controller parameter setting and simulation; with DGPS-RTK terminal yard cranes real-time operating system; temperature controller of heating furnace based on fuzzy neural network technology; design of direct digital synthesizer based on FPGA; a study for embedded software double-fault testability; design of the high-speed high-resolution latched comparator; design of a novel excitation circuit for low perming error fluxgate; design of SDH positive/zero/negative justification circuits based on FPGA; distribution network and multiple power bi-level programming; important position of information science in studying complex system; security research and measures for the internet of things; critical evaluation on steganography metrics; efficient scratchpad memory management for mobile multimedia application; modeling and simulation of FC-AE-ASM network; implementation of vehicle control system based on IPV6-CAN gateway; a provably secure e-cash scheme with loss-tracing; a note on optimal function for similarity measure in ontology application; a simple multi-models rendering framework - PM-OCMMRF; system design considerations for satellite communications on the move; an identity on resistance distances; simulation for view selection in data warehouse; internal cloud storage architecture implemented in crop germplasm resources data; analysis of precast piles for piling process; preparation and verification of a limit protective isolation structural analysis programs; research of cascade reservoirs flood limit level dynamic control based on game theory; hydrologic and hydraulic analysis of city flood control; the property of hierarchical structure in manufacturing; tools management solution for small enterprises; PLC-based laboratory intelligent management system; investigation on safety condition of cell phone charging; analyzing crash frequency by collision type at freeway diverge areas and study of logistics warehouse management system based on RFID.
B26: 2015 5th International Conference on Computer and Knowledge Engineering, ICCKE 2015 | C26: 2015 | D26: 0 | E26: https://www.scopus.com/inward/record.uri?eid=2-s2.0-84964444601&partnerID=40&md5=2ee5946f8c55e6a977c2c788fc1c7690 | F26: IR | H26: =countif(Survey!$E$2:$E$57,E26) -> 1 | I26: The proceedings contain 58 papers. The topics discussed include: optimization of budgeting type 2 diabetes through modeling disease burden; WS-TWSVM: weighted structural twin support vector machine by local and global information; necessity of laboratory blood tests in intensive care unit using data mining; diagnosis of type 2 diabetes using cost-sensitive learning; BetaProbe: a probability based method for predicting beta sheet topology using integer programming; design of an automated system for detection and classification of power quality disturbances; applying grey wolf optimizer-based decision tree c1assifer for cancer classification on gene expression data; designing a pervasive eye movement-based system for ALS and paralyzed patients; spectral clustering-based classification; a high-speed FPGA implementation of a bit-slice ultra-lightweight block cipher, RECTANGLE; and identification of gene signatures for classifying of breast cancer subtypes using protein interaction database and support vector machines.
A27: Li, J.; Liu, H.; Brown, M.; Kumar, P.; Challacombe, B.J.; Chandra, A.; Rottenberg, G.; Seneviratne, L.D.; Althoefer, K.; Dasgupta, P. | B27: Ex vivo study of prostate cancer localization using rolling mechanical imaging towards minimally invasive surgery | C27: 2017 | D27: 4 | E27: https://www.scopus.com/inward/record.uri?eid=2-s2.0-85013215035&doi=10.1016%2Fj.medengphy.2017.01.021&partnerID=40&md5=4c642cbfe3caf47a0794a3ac8dd7bc70 | F27: ST | H27: =countif(Survey!$E$2:$E$57,E27) -> 0 | I27: Rolling mechanical imaging (RMI) is a novel technique towards the detection and quantification of malignant tissue in locations that are inaccessible to palpation during robotic minimally invasive surgery (MIS); the approach is shown to achieve results of higher precision than is possible using the human hand. Using a passive robotic manipulator, a lightweight and force sensitive wheeled probe is driven across the surface of tissue samples to collect continuous measurements of wheel-tissue dynamics. A color-coded map is then generated to visualize the stiffness distribution within the internal tissue structure. Having developed the RMI device in-house, we aim to compare the accuracy of this technique to commonly used methods of localizing prostate cancer in current practice: digital rectal exam (DRE), magnetic resonance imaging (MRI) and transrectal ultrasound (TRUS) biopsy. Final histology is the gold standard used for comparison. A total of 126 sites from 21 robotic-assisted radical prostatectomy specimens were examined. Analysis was performed for sensitivity, specificity, accuracy, and predictive value across all patient risk profiles (defined by PSA, Gleason score and pathological score). Of all techniques, pre-operative biopsy had the highest sensitivity (76.2%) and accuracy (64.3%) in the localization of tumor in the final specimen. However, RMI had a higher sensitivity (44.4%) and accuracy (57.9%) than both DRE (38.1% and 52.4%, respectively) and MRI (33.3% and 57.9%, respectively). These findings suggest a role for RMI towards MIS, where haptic feedback is lacking. While our approach has focused on urological tumors, RMI has potential applicability to other extirpative oncological procedures and to diagnostics (e.g., breast cancer screening). © 2017
A28: Taruno, K.; Kurita, T.; Kuwahata, A.; Yanagihara, K.; Enokido, K.; Katayose, Y.; Nakamura, S.; Takei, H.; Sekino, M.; Kusakabe, M. | B28: Multicenter clinical trial on sentinel lymph node biopsy using superparamagnetic iron oxide nanoparticles and a novel handheld magnetic probe | C28: 2019 | D28: 59 | E28: https://www.scopus.com/inward/record.uri?eid=2-s2.0-85074788048&doi=10.1002%2Fjso.25747&partnerID=40&md5=70f25536527d62085c4b183b2e096bd8 | F28: SA | H28: =countif(Survey!$E$2:$E$57,E28) -> 0 | I28: Background: Sentinel lymph node biopsy is a standard staging procedure for early axillary lymph node-negative breast cancer. As an alternative to the currently used radioactive tracers for sentinel lymph node (SLN) detection during the surgical procedure, a number of studies have shown promising results using superparamagnetic iron oxide (SPIO) nanoparticles. Here, we developed a new handheld, cordless, and lightweight magnetic probe for SPIO detection. Methods: Resovist (SPIO nanoparticles) were detected by the newly developed handheld probe, and the SLN detection rate was compared to that of the standard radioisotope (RI) method using radioactive colloids (99mTc) and a blue dye (indigo carmine). This was a multicenter prospective clinical trial that included 220 patients with breast cancer scheduled for sentinel node biopsy after a clinical diagnosis of negative axillary lymph node from three facilities in Japan. Results: Of the 210 patients analyzed, SLN was detected in 94.8% (199/210 cases, 90% confidence interval [CI]) with our magnetic method and in 98.1% (206/210 cases, 90% CI) with the RI method. The magnetic method exceeded the threshold identification rate of 90%. Conclusion: This was the first clinical study to use a novel handheld magnetometer to detect SLN, which we demonstrate to be not inferior to the RI method. © 2019 Wiley Periodicals, Inc.
A29: Alam, M.W.; Wahid, K.A.; Goel, R.K.; Lukong, K.E. | B29: Development of a low-cost and portable smart fluorometer for detecting breast cancer cells | C29: 2019 | D29: 21 | E29: https://www.scopus.com/inward/record.uri?eid=2-s2.0-85061546246&doi=10.1364%2FBOE.10.000399&partnerID=40&md5=96f5a52dac94266494bd0706762bb7a5 | F29: SA | H29: =countif(Survey!$E$2:$E$57,E29) -> 0 | I29: Instruments that allow the detection of fluorescence signal are invaluable tools for biomedical and clinical researchers. The technique is widely used in cell biology to microscopically detect target proteins of interest in mammalian cells. Importantly, fluorescence microscopy finds major applications in cancer biology where cancer cells are chemically labelled for detection. However, conventional fluorescence detection instruments such as fluorescence imaging microscopes are expensive, not portable and entail potentially high maintenance costs. Here we describe the design, development and applicability of a low-cost and portable fluorometer for the detection of fluorescence signal emitted from a model breast cancer cell line, engineered to stably express the green fluorescent protein (GFP). This device utilizes a flashlight which works in the visible range as an excitation source and a photodiode as the detector. It also utilizes an emission filter to mainly allow the fluorescence signal to reach the detector while eliminating the use of an excitation filter and dichroic mirror, hence, making the device compact, low-cost, portable and lightweight. The custom-built sample chamber is fabricated with a 3D printer to house the detector circuitry. We demonstrate that the developed fluorometer is able to distinguish between the cancer cell expressing GFP and the control cell. The fluorometer we developed exhibits immense potential for future applicability in the selective detection of fluorescently-labelled breast cancer cells. © 2019 Optical Society of America.
A30: Nandhini, V.L.; Roy, S.K.; Babu, K. | B30: Detection of malignant tissue using metal dielectric interface based plasmonic biosensor | C30: 2019 | D30: 2 | E30: https://www.scopus.com/inward/record.uri?eid=2-s2.0-85071679965&doi=10.35940%2Fijitee.F1274.0486S419&partnerID=40&md5=71389f2e941c91469619606bd365f7d4 | F30: SA | H30: =countif(Survey!$E$2:$E$57,E30) -> 0 | I30: Metal-dielectric interface based Plasmonic biosensors commonly known as Surface Plasmonic Resonance (SPR) used in numerous applications in the analysis of bio reagents interaction and detection of the biological pathogen, cells and provides the advantage of real-time label-free efficient method. Sensitivity is a key parameter to measure sensor performance during development. Among all the plasmonic configurations, waveguide coupled configuration is most effective. In such a configuration an SPR and a waveguide are coupled through an evanescent field. This provides superior control over the biological reagent interaction, greater sensitivity and a multichannel-robust sensing device. Such devices are very small in size, lightweight as compared to prism coupled configuration which is bulky. These devices are also equipped to segregate specific sensor responses from non-specific response simultaneous multi analytes analysis. In view of the aforesaid benefits of waveguide coupled SPR, our present work focuses on a dual channel integrated optical waveguide based on metal dielectric interface biosensor. To study the behaviour of a waveguide coupled SPR sensor, we carried out analysis and simulation of SPR on multilayer geometries using tumour-associated antigens (TAAs). First, we started with the analysis of an SPR in the multi-layer intersection and observed the effect of variation of material characteristics on SPR profile. Further, extended our investigation to multilayered optical waveguide and the propagation constant was calculated. TAA and Newton’s method were used for Lung Cancer and Breast Cancer infected tissue and sensitivity 300nm/RIU obtained. © BEIESP.
B31: 2nd International Conference on Healthcare Science and Engineering, Healthcare 2018 | C31: 2019 | D31: 0 | E31: https://www.scopus.com/inward/record.uri?eid=2-s2.0-85065909723&partnerID=40&md5=1d86e21bff3a5377d0081b262702121e | F31: IR | H31: =countif(Survey!$E$2:$E$57,E31) -> 1 | I31: The proceedings contain 21 papers. The special focus in this conference is on Healthcare Science and Engineering. The topics include: Privacy management in social network data publishing with community structure; multidimensional correlation hierarchical differential privacy for medical data with multiple privacy requirements; injecting differential privacy in rules extraction of rough set; a lightweight neural network to detect arrhythmias; bayesian differential privacy for high-dimensional medical data optimization; Auxiliary force EEG (AFEEG) recognition oriented to stroke patients; a multi-valued fuzzy logic for qualitative reasoning in healthcare; a new approach for anonymizing relational and transaction data; fall detection using a multistage deep convolutional network architecture; robust feature selection method of radiomics for grading glioma; Performance evaluation of RPL-based sensor data collection in challenging IoT environment; low-cost system for travel aid and obstacles detection for the visually impaired people; cardiovascular disease risk prediction based on random forest; ECG beat classification based on deep bidirectional long short-term memory recurrent neural network; deep convolutional neural networks for electrocardiogram classification; transfer learning-based behavioural task decoding from brain activity; fine-tuning ResNet for breast cancer classification from mammography; lung sound diagnosis with deep convolutional neural network and two-stage pipeline model; an improved data anonymization algorithm for incomplete medical dataset publishing.
A32: Liu, S.; Ren, J.; Chen, Z.; Hu, K.; Xiao, F.; Li, X.; Gao, X. | B32: EffiDiag: An Efficient Framework for Breast Cancer Diagnosis in Multi-Gigapixel Whole Slide Images | C32: 2020 | D32: 5 | E32: https://www.scopus.com/inward/record.uri?eid=2-s2.0-85100334328&doi=10.1109%2FBIBM49941.2020.9313511&partnerID=40&md5=fb3d8f43c53000a15005cfd528649a9e | F32: P | G32: Y | H32: =countif(Survey!$E$2:$E$57,E32) -> 0 | I32: Breast cancer diagnosis in multi-gigapixel whole slide images (WSIs) is an important task that highly relevant to cancer grading and prognosis. In recent years, many computer-aided diagnosis methods were proposed and achieved promising performance. However, they mostly suffer from heavy computational burden that becomes a significant barrier to clinical practice. Efficient solutions are urgently demanded but still less studied. In this paper, we propose a novel framework named EffiDiag for a fast and lightweight breast cancer diagnosis. To this end, a loss-modified U-net is developed at first to enable a fast suspected cancer Region Of Interest (ROI) localization. Therefore the subsequent patch-based classification, which commonly executes at the finest magnification hundreds of thousands times per WSI for cancer identification, could be carried out on these ROIs only rather than the whole WSI for speedup. Meanwhile, a super-efficient convolutional neural network (CNN) is devised to optimize the classification speed and resource consumption per classification. Experiments on the Camelyonl6 benchmark demonstrate, by integrating the two contributions into a well-established approach, 47x inference acceleration is obtained with limited accuracy drop, yet with much less resource consumption even compared to popular lightweight networks. © 2020 IEEE.
A33: Sanghavi, F.; Kezebou, L.; Panetta, K.; Agaian, S. | B33: Breast cancer classification using parametric free thresholding adjacency statistics based Fibonacci patterns | C33: 2020 | D33: 2 | E33: https://www.scopus.com/inward/record.uri?eid=2-s2.0-85096352764&doi=10.1117%2F12.2558613&partnerID=40&md5=35bb3dd9c3a25059486a1936eef82f45 | F33: P | G33: Y | H33: =countif(Survey!$E$2:$E$57,E33) -> 0 | I33: According to the American cancer society, the average risk of women getting diagnosed with breast cancer during their life is 13%. The World Health Organization also reports that the number of cancer cases is projected to rise to 19.3 million by 2025. Recent research works point out that physicians can only diagnose cancer with 79% accuracy while machine learning procedures achieve 91% accuracy or more. The current challenges are early cancer detection and the efficient and accurate diagnosis of histopathology tissue samples. Several Deep Learning breast cancer classification models have been developed to assist medical practitioners. However, these methods are data hungry and require thousands of training image samples, often coupled with data augmentation to achieve satisfactory results with long training hours. In this paper, we propose a machine learning classification model by integrating the Parameter free Thresholding Adjacency Statistics (PFTAS) with Fibonacci-p patterns for breast cancer detection. Computer simulations on BreakHis cancer datasets in comparison to other machine learning and deep learning-based methods show that (i) the presented method helps eliminate dependence on large training data and data augmentation, (ii) robustness to noise and background stains, and (iii) lightweight model easy to train and deploy. © 2020 SPIE
A34: Roslidar, R.; Rahman, A.; Muharar, R.; Syahputra, M.R.; Arnia, F.; Syukri, M.; Pradhan, B.; Munadi, K. | B34: A Review on Recent Progress in Thermal Imaging and Deep Learning Approaches for Breast Cancer Detection | C34: 2020 | D34: 134 | E34: https://www.scopus.com/inward/record.uri?eid=2-s2.0-85087800211&doi=10.1109%2FACCESS.2020.3004056&partnerID=40&md5=6b6ab728d09e8e7a1c908b4e78500b47 | F34: P | G34: Y | H34: =countif(Survey!$E$2:$E$57,E34) -> 0 | I34: Developing a breast cancer screening method is very important to facilitate early breast cancer detection and treatment. Building a screening method using medical imaging modality that does not cause body tissue damage (non-invasive) and does not involve physical touch is challenging. Thermography, a non-invasive and non-contact cancer screening method, can detect tumors at an early stage even under precancerous conditions by observing temperature distribution in both breasts. The thermograms obtained on thermography can be interpreted using deep learning models such as convolutional neural networks (CNNs). CNNs can automatically classify breast thermograms into categories such as normal and abnormal. Despite their demostrated utility, CNNs have not been widely used in breast thermogram classification. In this study, we aimed to summarize the current work and progress in breast cancer detection based on thermography and CNNs. We first discuss of breast thermography potential in early breast cancer detection, providing an overview of the availability of breast thermal datasets together with publicly accessible. We also discuss characteristics of breast thermograms and the differences between healthy and cancerous thermographic patterns. Breast thermogram classification using a CNN model is described step by step including a simulation example illustrating feature learning. We cover most research related to the implementation of deep neural networks for breast thermogram classification and propose future research directions for developing representative datasets, feeding the segmented image, assigning a good kernel, and building a lightweight CNN model to improve CNN performance. © 2013 IEEE.
A35: Koma’rudin, N.; Zakaria, Z.; Soh, P.J.; Lago, H.; Alsariera, H.; Hassan, N. | B35: A review of recent microwave breast imaging | C35: 2020 | D35: 4 | E35: https://www.scopus.com/inward/record.uri?eid=2-s2.0-85092131911&doi=10.15866%2Firecap.v10i4.18560&partnerID=40&md5=8ce1c48bc14fe53278896f221f0c083c | F35: P | G35: Y | H35: =countif(Survey!$E$2:$E$57,E35) -> 0 | I35: Cancer is an asymptomatic disease that can easily affect tissues in multiple parts of the body, and it is one of the leading causes of death. Therefore, it is crucial to detect cancer tissues at the early stage. Moreover, measurement techniques and instruments that can be used for their backscattered signal gathering, processing and image reconstruction are crucial to ensure the accuracy of generated image; hence, the accuracy of tumour detection in breasts. One of the most critical components that should be carefully designed in such systems is the radiator, which functions as the main sensing component. Ideally, it should be lightweight, compact, wideband and unidirectional. By using such radiator, the performance of the antennas can be improved in terms of directivity, gain, efficiency and Specific Absorption Rate (SAR) to result in measurements with close accuracy compared to conventional medical imaging. This paper presents a review of the sensing requirements for microwave breast imaging application, which is aimed to provide a proper understanding, importance and recent developments of radiator and hardware for microwave imaging (MWI) application. © 2020 Praise Worthy Prize S.r.l.-All rights reserved.
A36: Moussa, M.N.; Madi, M.A.; Kabalan, K.Y. | B36: Miniaturized Inward Fractal Antenna for Breast Cancer Detection | C36: 2021 | D36: 6 | E36: https://www.scopus.com/inward/record.uri?eid=2-s2.0-85126741088&doi=10.1109%2FICECET52533.2021.9698733&partnerID=40&md5=187048564131139517e83cff935e163d | F36: SA | H36: =countif(Survey!$E$2:$E$57,E36) -> 0 | I36: The number of cancer diagnosed patients is rapidly increasing nowadays. Therefore, researchers are putting tremendous efforts to achieve efficient early cancer detection techniques in order to improve the survival rates as much as possible. Along this line and using EM detection approach, a miniaturized inward fractal antenna of size text{10} times 10 text{mm}{2} {(0.25lambdatimes 0.25lambda)} is designed, simulated in HFSS, fabricated on an FR4 substrate, and measured using a VNA network analyzer. It shows good impedance matching at 7.7 GHz with a gain of 2.9 dBi. This antenna is a good candidate for detecting the presence of a breast tumor because it is easy to fabricate by chemical etching with a low cost. Also, having a lightweight of 2g and a small size makes it suitable for wearable detection systems. © 2021 IEEE.
B37: International Conference on Intelligent Computing and Networking, IC-ICN 2020 | C37: 2021 | D37: 0 | E37: https://www.scopus.com/inward/record.uri?eid=2-s2.0-85096498383&partnerID=40&md5=96864cec68a1d7daf114c68cb5099620 | F37: IR | H37: =countif(Survey!$E$2:$E$57,E37) -> 1 | I37: The proceedings contain 27 papers. The special focus in this conference is on Intelligent Computing and Networking. The topics include: Exploiting Processor Variability for Efficient Application Mapping; data Sharing Over the Cloud Based on Ring Signature; data Analytics on Columnar Databases in Big Data Environment; real Time Multiple Object Detection on Low-Constrained Devices using Lightweight Deep Neural Network; Researcher Framework Using MongoDB and FCM Clustering for Prediction of the Future of Patients from EHR; performance Level Evaluation of Cryptographic Algorithms; driver Activity Monitoring Using MobileNets; a Review of Deep Learning Techniques Used in Breast Cancer Image Classification; Prediction of nMAG in PMIPv6 with the Help of MN Positions; surveillance System for Intruder Detection Using Facial Recognition; clinical Risk Prediction of Acute Coronary Syndrome Using Deep Learning Approach; genetic Algorithm for Feature Selection and Parameter Optimization to Enhance Learning on Framingham Heart Disease Dataset; securing IoT Devices Generated Data Using Homomorphic Encryption; Secure Data Aggregation and Data Transmission Using HMAC Protocol in Cluster Base Wireless Sensor Network; performance Evaluation of Adversarial Examples on Deep Neural Network Architectures; study on Analysis of Gene Expression Dataset and Identification of Differentially Expressed Genes; A Modified EDDKA Routing Approach to Enhance Quality of Service (QoS)-Enabled Data Dissemination in VANETs; a Novel and Secure Approach for Quantum Key Distribution in a Cloud Computing Environment; voting Using Blockchain Technology; deepfake Detection Approaches Using Deep Learning: A Systematic Review; secured Crowdfunding Platform Using Blockchain; review of Wireless Sensor Network Security Schemes; development of Agriculture Field Using Machine Learning.
B38: International Conference on Evolving Technologies for Computing, Communication and Smart World, ETCCS 2020 | C38: 2021 | D38: 0 | E38: https://www.scopus.com/inward/record.uri?eid=2-s2.0-85097683791&partnerID=40&md5=343726d9201692790d3e0204dad8e140 | F38: IR | H38: =countif(Survey!$E$2:$E$57,E38) -> 1 | I38: The proceedings contain 40 papers. The special focus in this conference is on Evolving Technologies for Computing, Communication and Smart World. The topics include: Event-Triggered Share Price Prediction; a Review: Efficient Transportation—Future Aspects of IoV; Compact High Gain 28 GHz Concentric Circular Director Low-Cost Antenna for 5G Millimeter-Wave Communication; preface; toward Response-Type Identification for the Real Time; questionnaire-Based Prediction of Hypertension Using Machine Learning; nature-Inspired Computing Behaviour of Cellular Automata; a Survey on Transport Layer Protocols for Reliable and Secure Wireless Sensor Networks; A Lightweight Exchangeable Encryption Scheme for IoT Devices Based on Vigenere Cipher and MLS Keystream; improving Steepest Descent Method by Learning Rate Annealing and Momentum in Neural Network; fingerprint and Face-Based Secure Biometric Authentication System Using Optimized Robust Features; DevOps, DevSecOps, AIOPS- Paradigms to IT Operations; Optimized Route Discovery and Node Registration for FANET; 4.1 GHz Low-Phase Noise Differential XCP LC-VCO with High Q and LC Noise Filtering; secured Surveillance Storage Model Using Blockchain; automatic Leaf Species Recognition Using Deep Neural Network; information Retrieval in Financial Documents; VNF Security in Telco Environment; Rank-Level Fusion of Random Indexing, Word Embedding, and TF-IDF-Based Rankings for Clinical Document Retrieval; a Novel Feature Engineering Approach for Twitter-Based Text Sentiment Analysis; Survey on DDoS and EDoS Attack in Cloud Environment; preprocessing Steps for Opinion Mining on Tweets; machine Learning-Based Lightweight Android Malware Detection System with Static Features; area and Power Efficient 2 Bit Multiplier by Using Enhanced Half Adder; the Modified Algorithm of Quantum Key Distribution System Synchronization; breast Cancer Classification Using Transfer Learning.
A39: Ahmad, B.; Sun, S.; Li, J.; Lidan, B. | B39: Comparative Study of Deep Learning Models For Automatic Detection of Metastases in HE Stained Images | C39: 2021 | D39: 4 | E39: https://www.scopus.com/inward/record.uri?eid=2-s2.0-85125349633&doi=10.1109%2FICCIS54243.2021.9676187&partnerID=40&md5=1f418c7a52230bcb6b8e2c667c7f672a | F39: P | G39: Y | H39: =countif(Survey!$E$2:$E$57,E39) -> 0 | I39: Deep learning has gained the attention of researchers around the world. We used several deep learning models to check whether they could potentially be used as a clinical utility by pathologists to detect lymph node metastases in tissue sections of women with breast cancer to save time and reduce the burden on healthcare. For that purpose, we selected three deep learning models of different depths. The deepest one (DenseNet201), medium depth (Resent50), lightweight (Mobie/Net) and trained them in different experiments under various hyperparameters settings from scratch. The test set consists of 32000 histopathological images. We used absolute accuracy, sensitivity, specificity, and F1-score as a performance measure. Apart from these measures, we observe the effect of data augmentation and the number of epochs on the classification performance. We achieved an average accuracy of 85.6%, 87.5%, and 88.4% for MobileNet V1, ResNet50, and DenseNet201, respectively, which further improves to 91.1 %, 93.8%, and 95.7%, respectively, when augmented images are used in the training set. The performance of all deep learning models was on par with that of expert pathologists reported in different studies. We may expect that deep learning could be an exceptional utility for clinicians in real-time diagnosis too. © 2021 IEEE.
