Workbook

Sheet Scopus_WOS
A1: C | B1: Article Title | C1: Publication Year | D1: Source Title | E1: Cited Reference Count | F1: Affiliations | G1: Abstract | H1: Author Keywords | I1: Keywords Plus | J1: Publisher | K1: Document Type | L1: Open Access Designations | M1: status | N1: In_paper | O1: Exclusion reason
A2: Modu, F; Prasad, R; Aliyu, F | B2: development of a knowledge-distillation-based breast cancer classifier for lmics: comparison with pruning and quantization | C2: 2025 | D2: ELECTRONICS | E2: 71 | F2: African University of Science & Technology; King Fahd University of Petroleum & Minerals | G2: Breast cancer (BC) mortality rates remain high in Low- and Middle-Income Countries (LMICs) due to limited awareness, poverty, and inadequate medical facilities that hinder early detection. Although deep learning models have achieved high accuracy in BC detection (BCD), they require substantial computational resources, making them unsuitable for deployment in remote or rural areas. This study proposes a lightweight convolutional neural network (CNN) using Knowledge Distillation (KD) for BCD, where a large Teacher Model (TM) transfers learned representations to a smaller Student Model (SM), which is better suited for deployment on low-power devices. We compare it with two prominent model compression techniques: pruning and quantization. Experimental results indicate that the TensorFlow Lite (TFLite)-optimized Student Model (SM_TFLite) achieved 97.67% accuracy, representing a 2.33% relative loss to its teacher, a result comparable to other compression techniques. Its mean accuracy is 73.97% with a 95% Confidence Interval of [65.04%, 82.90%] in a cross-dataset experiment. However, SM_TFLite was the most compact (5.21 kB) and fastest (3.3 ms latency), outperforming both pruned (2924.31 kB, 13.68 ms) and quantized models (746-751 kB, 4-5 ms). Evaluation on a Raspberry Pi 4 Model B demonstrated that all models exhibited similar CPU and memory usage, with SM_TFLite causing only a minor increase in device temperature. These results demonstrate that KD combined with TFLite conversion offers the best trade-off between accuracy, compactness, and speed. | H2: breast cancer detection; lightweight CNN; Knowledge Distillation; pruning; quantization; IoT; healthcare; telemedicine; breast cancer; deep learning; convolutional neural network; Keras | J2: MDPI | K2: Article | L2: gold | M2: P | N2: Y
A3: Yeh, WC; Shia, WC; Hsu, YT; Huang, CH; Lee, YS | B3: a lightweight breast cancer mass classification model utilizing simplified swarm optimization and knowledge distillation | C3: 2025 | D3: BIOENGINEERING-BASEL | E3: 55 | F3: National Tsing Hua University; Chung Yuan Christian University; Changhua Christian Hospital; Chang Gung University; Feng Chia University | G3: In recent years, an increasing number of women worldwide have been affected by breast cancer. Early detection is crucial, as it is the only way to identify abnormalities at an early stage. However, most deep learning models developed for classifying breast cancer abnormalities tend to be large-scale and computationally intensive, often overlooking the constraints of cost and limited computational resources. This research addresses these challenges by utilizing the CBIS-DDSM dataset and introducing a novel concatenated classification architecture and a two-stage strategy to develop an optimized, lightweight model for breast mass abnormality classification. Through data augmentation and image preprocessing, the proposed model demonstrates a superior performance compared to standalone CNN and DNN models. The two-stage strategy involves first constructing a compact model using knowledge distillation and then refining its structure with a heuristic approach known as Simplified Swarm Optimization (SSO). The experimental results confirm that knowledge distillation significantly enhances the model's performance. Furthermore, by applying SSO's full-variable update mechanism, the final model-SSO-Concatenated NASNetMobile (SSO-CNNM)-achieves outstanding performance metrics. It attains a compression rate of 96.17%, along with accuracy, precision, recall, and AUC scores of 96.47%, 97.4%, 94.94%, and 98.23%, respectively, outperforming other existing methods. | H3: lightweight breast cancer mass classification model; simplified swarm optimization; knowledge distillation; convolutional neural networks | J3: MDPI | K3: Article | L3: Green Submitted, gold | M3: {=IFERROR( INDEX(survey_paper_2026!$F:$F, MATCH(LOWER(TRIM(B3)), LOWER(TRIM(survey_paper_2026!$B:$B)),0) ), "New" )} -> P | N3: {=IFERROR( INDEX(survey_paper_2026!$G:$G, MATCH(LOWER(TRIM(B3)), LOWER(TRIM(survey_paper_2026!$B:$B)),0) ), "New" )} -> Y
A4: Khalid, N; Dagli, C; Obafenai-Ajayi, T; Wunsch, DW II | B4: knowledge distillation-based tinyml model for breast cancer detection using real and wasserstein gan-generated microwave imaging data | C4: 2025 | D4: 2025 47TH ANNUAL INTERNATIONAL CONFERENCE OF THE IEEE ENGINEERING IN MEDICINE AND BIOLOGY SOCIETY (EMBC) | E4: 17 | F4: University of Missouri System; Missouri University of Science & Technology; University of Missouri System; Missouri University of Science & Technology; Missouri State University | G4: Tiny Machine Learning (TinyML) offers a transformative approach to efficient, intelligent cancer diagnostics on edge devices. However, designing optimized TinyML models for breast cancer diagnosis using Microwave Imaging datasets remains a challenge due to domain-specific customization requirements. To address this, we propose a novel Knowledge Distillation framework, where a teacher model, built using residual convolutional neural networks, transfers its knowledge to a lightweight student model, enhancing efficiency while maintaining high accuracy. The teacher model achieves a 95.42% accuracy on test data. Through knowledge distillation, the student model attains 95.32% accuracy while achieving a 96% reduction in model size, significantly enhancing computational efficiency without compromising performance. Without distillation, the student model reaches a testing accuracy of 86.5%. A major contribution of this work is the generation of a highquality synthetic breast cancer dataset to address the scarcity of microwave imaging data. We employ a Wasserstein Generative Adversarial Network with Gradient Penalty (WGAN-GP) to synthesize realistic breast cancer scans, ensuring reliability through rigorous validation with a one-class Support Vector Machine. By training all models on a combination of real and synthetic datasets, our approach enhances robustness, making TinyML-powered breast cancer detection more viable for realworld deployment. | J4: IEEE | K4: Proceedings Paper | M4: P | N4: Y
A5: Sepahvand, M; Abdali-Mohammadi, F | B5: joint learning method with teacher-student knowledge distillation for on-device breast cancer image classification | C5: 2023 | D5: COMPUTERS IN BIOLOGY AND MEDICINE | E5: 46 | F5: Razi University | G5: The deep learning models such as AlexNet, VGG, and ResNet achieved a good performance in classifying the breast cancer histopathological images in BreakHis dataset. However, these models are not practically appro-priate due to their computational complexity and too many parameters; as a result, they are rarely utilized on devices with limited computational resources. This paper develops a lightweight learning model based on knowledge distillation to classify the histopathological images of breast cancer in BreakHis. This method employs two teacher models based on VGG and ResNext to train two student models, which are similar to the teacher models in development but have fewer deep layers. In the proposed method, the adaptive joint learning approach is adopted to transfer the knowledge in the final-layer output of a teacher model along with the feature maps of its middle layers as the dark knowledge to a student model. According to the experimental results, the student model designed by ResNeXt architecture obtained the recognition rate 97.09% for all histopathological images. In addition, this model has-69.40 million fewer parameters,-0.93 G less GPU memory use, and 268.17 times greater compression rate than its teacher model. While in the student model the recognition rate merely dropped down to 1.75%. The comparisons indicated that the student model had a rather acceptable outputs compared with state-of-the-art methods in classifying the images of breast cancer in BreakHis. | H5: Breast cancer images; On -device classification; Knowledge distillation; Teacher-student learning; Lightweight classification | I5: NEURAL-NETWORKS; COMPRESSION | J5: PERGAMON-ELSEVIER SCIENCE LTD | K5: Article | M5: P | N5: Y
A6: Meraj, T; Alosaimi, W; Alouf, B; Rauf, HT; Kumar, SA; Dama, R; Alyami, H | B6: a quantization assisted u-net study with ica and deep features fusion for breast cancer identification using ultrasonic data | C6: 2021 | D6: PEERJ COMPUTER SCIENCE | E6: 57 | F6: COMSATS University Islamabad (CUI); Taif University; Taif University; University of Bradford; Silesian University of Technology | G6: Breast cancer is one of the leading causes of death in women worldwide-the rapid increase in breast cancer has brought about more accessible diagnosis resources. The ultrasonic breast cancer modality for diagnosis is relatively cost-effective and valuable. Lesion isolation in ultrasonic images is a challenging task due to its robustness and intensity similarity. Accurate detection of breast lesions using ultrasonic breast cancer images can reduce death rates. In this research, a quantization-assisted U-Net approach for segmentation of breast lesions is proposed. It contains two step for segmentation: (1) U-Net and (2) quantization. The quantization assists to U-Net-based segmentation in order to isolate exact lesion areas from sonography images. The Independent Component Analysis (ICA) method then uses the isolated lesions to extract features and are then fused with deep automatic features. Public ultrasonic-modality-based datasets such as the Breast Ultrasound Images Dataset (BUSI) and the Open Access Database of Raw Ultrasonic Signals (OASBUD) are used for evaluation comparison. The OASBUD data extracted the same features. However, classification was done after feature regularization using the lasso method. The obtained results allow us to propose a computer-aided design (CAD) system for breast cancer identification using ultrasonic modalities. | H6: Quantization; Features fusion; Breast cancer; Ultrasonic images; Computer vision; Image processing | I6: CONVOLUTIONAL NEURAL-NETWORK; IMAGE SEGMENTATION; CLASSIFICATION; LESIONS | J6: PEERJ INC | K6: Article | L6: Green Submitted, gold | M6: SA | N6: {=IFERROR( INDEX(survey_paper_2026!$G:$G, MATCH(LOWER(TRIM(B6)), LOWER(TRIM(survey_paper_2026!$B:$B)),0) ), "New" )} -> New
A7: Hossain, MB; Shaban, M | B7: low-complexity low-memory vgg models for accurate diagnosis of breast cancer | C7: 2024 | D7: SOUTHEASTCON 2024 | E7: 14 | F7: University of South Alabama | G7: Breast cancer is considered the most prevalent cancer among women and may spread to other organs if it is not detected and treated early. In addition, mammography is the primary imaging modality and is widely used for screening and diagnosing breast cancer. Recent studies have applied deep learning for mammogram-based breast cancer detection. However, these methods have high computational and memory requirements. In this paper, we propose low-complexity light-weight VGG-16 and VGG-19 models that are able to detect breast cancer at an accuracy of 98% and a sensitivity of 95%. While the performance of the proposed models is comparable to that of the-state-of-the-art architectures, the proposed models were extensively compressed using a novel combination of filter pruning, node pruning and post-training quantization offering up to 98.4% reduction in the number of learning parameters, up to 97.6% drop in the number of FLOPs, and almost 99.6% decrease in the allocated memory. This will potentially facilitate the efficient implementation of the models on edge Internet of Things (IoT) devices deployed in future IoT healthcare platforms. | H7: Breast Cancer; Mammography; Deep Learning; Pruning; Quantization | J7: IEEE | K7: Proceedings Paper | M7: P | N7: Y
A8: Si, JL; Jia, W; Jiang, HF | B8: breast cancer histopathology images classification through multi-view augmented contrastive learning and pre-learning knowledge distillation | C8: 2024 | D8: IEEE ACCESS | E8: 43 | F8: Ningxia University; Ningxia Medical University | G8: Breast cancer is one of the most common malignant tumors in women, and accurate classification of benign and malignant breast cancer histopathology images is critical for diagnosis and treatment. Knowledge distillation techniques have recently received considerable attention for enabling cost-effective image classification of breast cancer histopathology images. However, there are still challenges, including the inefficient extraction of global and local features from breast cancer histopathology images by the teacher network, and the over-prioritization of feature fusion within the same encoder layer, which tends to neglect valuable information from adjacent encoder layers during knowledge extraction. To address these challenges, we propose a method that combines multi-view augmented contrastive learning and pre-learning knowledge distillation. Multi-view augmented contrastive learning improves the ability of the teacher network to extract global and local features. Pre-learning knowledge distillation merges features from adjacent encoder layers of the teacher network, reducing feature loss between these layers. Empirical experiments demonstrate the effectiveness of our proposed method in classifying histopathology images of benign and malignant breast cancer, achieving excellent results on the BreakHis dataset. These results confirm our method as an effective tool for the classification of benign and malignant breast cancer histopathology images. | H8: Breast cancer; Histopathology; Feature extraction; Self-supervised learning; Computational modeling; Knowledge transfer; Knowledge representation; Knowledge discovery; Contrast resolution; Image classification; Biomedical imaging; Knowledge distillation; contrastive learning; breast cancer histopathology image; global feature; local feature | I8: ATTENTION; STATISTICS | J8: IEEE-INST ELECTRICAL ELECTRONICS ENGINEERS INC | K8: Article | L8: Green Submitted, gold | M8: P | N8: Y
A9: Garg, S; Singh, P | B9: transfer learning based lightweight ensemble model for imbalanced breast cancer classification | C9: 2023 | D9: IEEE-ACM TRANSACTIONS ON COMPUTATIONAL BIOLOGY AND BIOINFORMATICS | E9: 42 | F9: National Institute of Technology (NIT System); National Institute of Technology Raipur | G9: Automated classification of breast cancer can often save lives, as manual detection is usually time-consuming & expensive. Since the last decade, deep learning techniques have been most widely used for the automatic classification of breast cancer using histopathology images. This paper has performed the binary and multi-class classification of breast cancer using a transfer learning-based ensemble model. To analyze the correctness and reliability of the proposed model, we have used an imbalance IDC dataset, an imbalance BreakHis dataset in the binary class scenario, and a balanced BACH dataset for the multi-class classification. A lightweight shallow CNN model with batch normalization technology to accelerate convergence is aggregated with lightweight MobileNetV2 to improve learning and adaptability. The aggregation output is fed into a multilayer perceptron to complete the final classification task. The experimental study on all three datasets was performed and compared with the recent works. We have fine-tuned three different pre-trained models (ResNet50, InceptionV4, and MobilNetV2) and compared it with the proposed lightweight ensemble model in terms of execution time, number of parameters, model size, etc. In both the evaluation phases, it is seen that our model outperforms in all three datasets. | H9: Convolution; Breast cancer; Feature extraction; Computational modeling; Computer architecture; Transfer learning; Deep learning; lightweight model; classification; ensemble | J9: IEEE COMPUTER SOC | K9: Article | M9: {=IFERROR( INDEX(survey_paper_2026!$F:$F, MATCH(LOWER(TRIM(B9)), LOWER(TRIM(survey_paper_2026!$B:$B)),0) ), "New" )} -> P | N9: {=IFERROR( INDEX(survey_paper_2026!$G:$G, MATCH(LOWER(TRIM(B9)), LOWER(TRIM(survey_paper_2026!$B:$B)),0) ), "New" )} -> Y
A10: Maisen, C; Auephanwiriyakul, S; Theera-Umpon, N | B10: learning vector quantization inference classifier in breast abnormality classification | C10: 2018 | D10: JOURNAL OF INTELLIGENT & FUZZY SYSTEMS | E10: 33 | F10: Chiang Mai University; Chiang Mai University; Chiang Mai University; Chiang Mai University | G10: The Mammographic image is a tool for observing breast cancer. Analyzing difficulties include shape, size variety, nearby tissue, and noise. In this paper, we propose a method to classify mammogram abnormalities based on learning vector quantization inference classifier (LVQIC) with fuzzy co-occurrence matrix (FCOM) textural features. The system is implemented on the Mini-MIAS data set with a 5-class problem, i.e., the classification of architectural distortion (AD), spiculated mass (SPIC), calcification (CALC), well-defined/circumscribed masses (CIRC), and normal (NORM). The implementation is also on a 2-class problem consisting of AD-vs-All, SPIC-vs-All, CALC-vs-All, CIRC-vs-All, and NORM/abnormal. The best blind test result is from the 5-class problem with features from fuzzy co-occurrence matrix (FCOM) with 4 clusters, co-occurrence distance d = 2, and 16 prototypes per class. The best classification result is 100% correct classification with 0.03, 0.04, 0.06, and 0.02 false positive rate for AD, SPIC, CALC, and CIRC, respectively. | H10: Mammograms; breast cancer; breast abnormality detection; neuro fuzzy; feature selection | I10: MASS DETECTION; MAMMOGRAMS | J10: IOS PRESS | K10: Article; Proceedings Paper | M10: SA | N10: {=IFERROR( INDEX(survey_paper_2026!$G:$G, MATCH(LOWER(TRIM(B10)), LOWER(TRIM(survey_paper_2026!$B:$B)),0) ), "New" )} -> New
A11: Jiang, L; Zhang, C; Zhang, H; Cao, H | B11: a lightweight spatially-aware classification model for breast cancer pathology images | C11: 2024 | D11: BIOCYBERNETICS AND BIOMEDICAL ENGINEERING | E11: 62 | F11: Shandong University of Traditional Chinese Medicine | G11: Breast cancer is a prevalent malignant tumour with high global incidence. Its diagnosis relies primarily on the analysis of pathological breast images. Owing to the complex organisation of the tumour microenvironment, neural network models are essential as efficient classification tools in the field of pathological image analysis. This study introduced spatially-aware attention swift parallel convolution network (SPA-SPCNet), a lightweight and low-latency model for classifying breast pathologies. A novel module for multi-scale feature extraction was constructed using a depthwise separable convolution method. It focuses on the multi-scale features of pathological images to alleviate recognition problems caused by similar local features in breast cancer tissues. The module concatenates the convolutions of different kernels from three branches. Second, a lightweight dynamic spatially-aware attention module was introduced to integrate the visual graph convolutional architecture in a branch. This allowed the model to capture the spatial structure and relationships in image, enabling better handling of the unique spatial distribution relationship between breast cancer tissue structures. The other branch utilises a self-attention mechanism in the transformer. The module can dynamically adjust the attention of the model to different regions in the image, allowing it to focus on the key features of the complex spatial distribution of breast cancer tissue. This feature fusion method enabled the model to capture both global semantics and local details. Compared with existing lightweight models, the proposed model has advantages in terms of tissue structure classification accuracy, parameter quantity, floating-point operations, and real-time inference speed, providing a powerful tool for computer-aided breast pathological image classification. | H11: Breast cancer classification; Multi-scale features; Graph convolutional network; Feature fusion; Lightweight network | I11: TRANSFORMER | J11: ELSEVIER | K11: Article | M11: P | N11: Y
A12: Kolla, B; Venugopal, P | B12: breast cancer diagnosis through knowledge distillation of swin transformer-based teacher-student models | C12: 2023 | D12: MACHINE LEARNING-SCIENCE AND TECHNOLOGY | E12: 26 | F12: Vellore Institute of Technology (VIT); VIT Vellore | G12: Breast cancer is a significant global health concern, emphasizing the crucial need for a timely and accurate diagnosis to enhance survival rates. Traditional diagnostic methods rely on pathologists analyzing whole-slide images (WSIs) to identify and diagnose malignancies. However, this task is complex, demanding specialized expertise and imposing a substantial workload on pathologists. Additionally, existing deep learning models, commonly employed for classifying histopathology images, often need enhancements to ensure their suitability for real-time deployment on WSI, especially when trained for small regions of interest (ROIs). This article introduces two Swin transformer-based architectures: the teacher model, characterized by its moderate size, and the lightweight student model. Both models are trained using a publicly available dataset of breast cancer histopathology images, focusing on ROIs with varying magnification factors. Transfer learning is applied to train the teacher model, and knowledge distillation (KD) transfers its capabilities to the student model. To enhance validation accuracy and minimize the total loss in KD, we employ the state-action-reward-state-action (SARSA) reinforcement learning algorithm. The algorithm dynamically computes temperature and a weighting factor throughout the KD process to achieve high accuracy within a considerably shorter training timeframe. Additionally, the student model is deployed to analyze malignancies in WSI. Despite the student model being only one-third the size and flops of the teacher model, it achieves an impressive accuracy of 98.71%, slightly below the teacher's accuracy of 98.91%. Experimental results demonstrate that the student model can process WSIs at a throughput of 1.67 samples s-1 with an accuracy of 82%. The proposed student model, trained using KD and the SARSA algorithm, exhibits promising breast cancer classification and WSI analysis performance. These findings indicate its potential for assisting pathologists in diagnosing breast cancer accurately and effectively. | H12: teacher model; student model; Swin-transformers; transfer learning; knowledge distillation; breast cancer histopathology | J12: IOP Publishing Ltd | K12: Article | L12: Green Submitted, gold | M12: P | N12: Y
A13: Ling, DC; Jiao, X | B13: mvkd-trans: a multi-view knowledge distillation vision transformer architecture for breast cancer classification based on ultrasound images | C13: 2025 | D13: ULTRASONIC IMAGING | E13: 38 | F13: Taiyuan University of Technology | G13: Breast cancer is the leading cancer threatening women's health. In recent years, deep neural networks have outperformed traditional methods in terms of both accuracy and efficiency for breast cancer classification. However, most ultrasound-based breast cancer classification methods rely on single-perspective information, which may lead to higher misdiagnosis rates. In this study, we propose a multi-view knowledge distillation vision transformer architecture (MVKD-Trans) for the classification of benign and malignant breast tumors. We utilize multi-view ultrasound images of the same tumor to capture diverse features. Additionally, we employ a shuffle module for feature fusion, extracting channel and spatial dual-attention information to improve the model's representational capability. Given the limited computational capacity of ultrasound devices, we also utilize knowledge distillation (KD) techniques to compress the multi-view network into a single-view network. The results show that the accuracy, area under the ROC curve (AUC), sensitivity, specificity, precision, and F1 score of the model are 88.15%, 91.23%, 81.41%, 90.73%, 78.29%, and 79.69%, respectively. The superior performance of our approach, compared to several existing models, highlights its potential to significantly enhance the understanding and classification of breast cancer. | H13: breast ultrasound; deep learning; knowledge distillation; multi-view learning; medical image analysis | I13: CONVOLUTIONAL NEURAL-NETWORK; FUSION | J13: SAGE PUBLICATIONS INC | K13: Article | M13: NA | N13: new | O13: Not accessible
A14: Sepahvand, M; Abdali-Mohammadi, F | B14: overcoming limitation of dissociation between md and mi classifications of breast cancer histopathological images through a novel decomposed feature-based knowledge distillation method | C14: 2022 | D14: COMPUTERS IN BIOLOGY AND MEDICINE | E14: 42 | F14: Razi University | G14: Magnification-independent (MI) classification is considered a promising method for detecting the histopathological images of breast cancer. However, it has too many parameters for real implementation due to dependence on input images in different magnification factors. In addition, magnification-dependent (MD) classification usually performs poorly on unseen samples, although it has lower input image sizes and fewer parameters. This paper proposes a novel method based on knowledge distillation (KD) to overcome the limitation of dissociation between MI classification and MD classification of breast cancer in histopathological images. The proposed KD method includes a pre-trained MI teacher model that is responsible for training an unprepared MD student model developed through only one magnification factor. In the proposed method, the decomposed feature maps of a teacher's intermediate layers are transferred as dark knowledge to a student. According to the experimental results, the student model developed through 40X images yielded accuracy rates of 99.41%, 99.26%, 99.14%, and 99.09% in response to unseen samples of 40X, 100X, 200X, and 400X images, respectively. Moreover, comparison results indicated the competitive performance of the proposed student model as opposed to the stateof-the-art method based on deep learning on BreakHis. | H14: Breast cancer; Histopathology; BreakHis; Knowledge distillation; Convolutional neural network | I14: DEEP NEURAL-NETWORKS; COMPRESSION; DIAGNOSIS; ALGORITHM | J14: PERGAMON-ELSEVIER SCIENCE LTD | K14: Article | M14: P | N14: Y
A15: Tang, YD; Zhou, DP; Flesch, RCC; Jin, T | B15: a multi-input lightweight convolutional neural network for breast cancer detection considering infrared thermography | C15: 2025 | D15: EXPERT SYSTEMS WITH APPLICATIONS | E15: 37 | F15: Fuzhou University; Universidade Federal de Santa Catarina (UFSC); Fuzhou University | G15: Although deep convolutional neural network (CNN) has been widely used in the breast cancer detection based on thermal imaging technology, this scenario still did not receive enough attention in the mobile devices with limited resource. In addition, there still exists challenge on how to assist front view thermal imaging by side one during breast cancer detection. This study proposes a multi-input lightweight CNN named Multi-light Net in order to achieve more accurate early detection for breast cancer, which combines the thermal image from multiple perspectives with the lightweight CNN on the basis of model performance and scale. In addition, a new weighted label smoothing regularization (WLSR) is proposed for the Multi-light Net with the purpose of increasing the network's generalization ability and classification accuracy. The experimental results demonstrate that the proposed approach by combining front view with side view can achieve more significant results than the common one using only front view during breast cancer detection, and the proposed Multi-light Net also exhibits an excellent performance with respect to the currently popular lightweight CNN. Furthermore, the proposed WLSR loss function can also lead to both faster convergence rate and more stable training process during network training and ultimately higher diagnostic accuracy for breast cancer. | H15: Breast cancer; Thermography; Multi-input; Lightweight; CNN | J15: PERGAMON-ELSEVIER SCIENCE LTD | K15: Article | M15: {=IFERROR( INDEX(survey_paper_2026!$F:$F, MATCH(LOWER(TRIM(B15)), LOWER(TRIM(survey_paper_2026!$B:$B)),0) ), "New" )} -> P | N15: {=IFERROR( INDEX(survey_paper_2026!$G:$G, MATCH(LOWER(TRIM(B15)), LOWER(TRIM(survey_paper_2026!$B:$B)),0) ), "New" )} -> Y
A16: Modu, F; Prasad, R; Aliyu, F | B16: lightweight cnn for resource-constrained bcd system using knowledge distillation | C16: 2025 | D16: IEEE ACCESS | E16: 94 | F16: African University of Science & Technology; King Fahd University of Petroleum & Minerals | G16: Breast cancer (BC) remains a leading cause of mortality among women worldwide, with over two million new cases annually. Early detection improves survival rates significantly, yet resource limitations in low- and middle-income countries (LMICs) hinder access to advanced diagnostic tools. While deep learning (DL) models have shown high accuracy in breast cancer detection (BCD), their computational complexity and hardware requirements make them impractical for deployment on low-power devices. To address this, we propose a lightweight convolutional neural network (CNN) for BCD, leveraging knowledge distillation (KD) to transfer knowledge from a complex teacher model (TM) to a smaller student model (SM). Our approach achieves up to 99.3% accuracy, 100% precision, and 99% recall while reducing the number of trainable parameters by 87% compared to conventional deep models. The proposed model successfully runs on a Raspberry Pi 4B with an inference time of 500 ms and memory usage of just 12% (of 8GB RAM), demonstrating its suitability for telemedicine and mobile diagnostics. Additionally, resource utilization experiments confirm that inference remains stable at 10% CPU usage and 40 degrees C when using a heat sink and fan, ensuring sustained deployment. Future work will explore federated learning for decentralized training, integration of multimodal data for enhanced diagnosis, and cloud-based model updates using delay-tolerant networks (DTNs) for remote healthcare applications. | H16: Computational modeling; Breast cancer; Convolutional neural networks; Accuracy; Medical services; Knowledge engineering; Internet of Things; Hardware; Deep learning; Data models; convolutional neural network; deep learning; Keras; knowledge distillation; teacher-student model; SDG3 | I16: BREAST-CANCER | J16: IEEE-INST ELECTRICAL ELECTRONICS ENGINEERS INC | K16: Article | L16: Green Submitted, gold | M16: {=IFERROR( INDEX(survey_paper_2026!$F:$F, MATCH(LOWER(TRIM(B16)), LOWER(TRIM(survey_paper_2026!$B:$B)),0) ), "New" )} -> P | N16: {=IFERROR( INDEX(survey_paper_2026!$G:$G, MATCH(LOWER(TRIM(B16)), LOWER(TRIM(survey_paper_2026!$B:$B)),0) ), "New" )} -> Y
A17: Ma, XY; Sun, L; Gao, JP; Dong, YM | B17: lmcnet: a lightweight and efficient model for multi-classification of breast cancer images | C17: 2025 | D17: SIGNAL IMAGE AND VIDEO PROCESSING | E17: 35 | F17: Hebei University of Economics & Business | G17: Breast cancer is currently one of the most common cancers among women worldwide. Computer-aided diagnosis (CAD) is crucial in reducing diagnostic costs and improving subsequent cancer treatment. Convolutional neural networks are widely used in CAD, but most existing models are high-complexity and multi-parameter architectures, which limits their practical application. To address this issue, this paper proposes LMCNet, a lightweight breast cancer multi-classification model. LMCNet reduces the model complexity by refactoring the basic units of ShuffleNetV2, introducing PAConv parallel convolution layers and combining depthwise separable convolution. In order to further improve the feature extraction ability of the model, an SAE attention module containing channel and spatial dimensions is introduced. The proposed model achieves high recognition accuracy with low resource consumption. Our method requires only 275.69 K parameters and 51.19 M FLOPs. Compared to ShuffleNetV2, LMCNet reduces parameters by approximately 78.63% and FLOPs by 66.18%. Compared with other classical models, the proposed model achieves the best recognition efficiency and the fastest inference speed. | H17: Breast cancer; Medical image classification; Lightweight CNN; ShuffleNetV2 | J17: SPRINGER LONDON LTD | K17: Article | M17: P | N17: Y
A18: Kumar, A; Sharma, A; Bharti, V; Singh, AK; Singh, SK; Saxena, S | B18: mobihisnet: a lightweight cnn in mobile edge computing for histopathological image classification | C18: 2021 | D18: IEEE INTERNET OF THINGS JOURNAL | E18: 43 | F18: Indian Institute of Technology System (IIT System); Indian Institute of Technology BHU Varanasi (IIT BHU Varanasi); National Institute of Technology (NIT System); National Institute of Technology Patna; Indian Council of Agricultural Research (ICAR); ICAR - Indian Veterinary Research Institute | G18: Recent advances in artificial intelligence (AI), especially convolutional neural networks (CNNs), alongside the digitization of histopathological images, have made the computer-aided diagnosis of breast cancer a reality. However, deep learning-based approaches are computationally expensive and have huge parameters, which makes them less affordable for edge devices. In order to make them affordable for edge devices, the whole classification model needs to be compressed while maintaining accuracy. Providing a low-cost solution for histopathological diagnosis in the recent edge-computing world is of utmost importance. Therefore, in this study, we propose MobiHisNet, an efficient and lightweight CNN model for histopathological image classification (HIC) based on MobileNet. MobiHisNet was successfully deployed on a Raspberry Pi, as well as three mobile devices, demonstrating its ability to run on a lightweight and portable processor. Our studies indicated that a depth parameter (gamma = 0.5) and a 16-bit quantization are the optimum parameters for the proposed model while balancing the accuracy, inference time, and memory peak requirements. Compared to the state-of-the-art, pretrained models, MobiHisNet has fewer parameters and calculations, resulting in faster image classification. This renders it more viable for production purposes and applications on edge devices. In addition, MobiHisNet is computationally faster than VGG16, ResNet50, Xception, and InceptionV3 by twenty-seven, eight, six, and five times, respectively. This also outperforms all the baseline models with the moderate model size and FLOP counts. Experiments on breast cancer HIC (BreakHis) data sets show superior performance of MobiHisNet on edge devices in terms of higher accuracy, lesser complexity, and lesser memory requirements. Thus, it has a high potential for deployment in mobile edge devices. | H18: Edge computing; histopathological classification; Internet of Everything (IoE); lightweight convolutional neural network (CNN); quantization | J18: IEEE-INST ELECTRICAL ELECTRONICS ENGINEERS INC | K18: Article | M18: P | N18: Y
A19: Liu, Y; Li, HP; Zhu, Z; Chen, C; Zhang, XJ; Jin, GS; Li, HT | B19: rsdcnet: an efficient and lightweight deep learning model for benign and malignant pathology detection in breast cancer | C19: 2025 | D19: DIGITAL HEALTH | E19: 29 | F19: Bengbu Medical University; Bengbu Medical University; Bengbu Medical University | G19: Background Breast cancer is a leading malignant tumor among women globally, with its pathological classification into benign or malignant directly influencing treatment strategies and prognosis. Traditional diagnostic methods, reliant on manual interpretation, are not only time-intensive and subjective but also susceptible to variability based on the pathologist's expertise and workload. Consequently, the development of an efficient, automated, and precise pathological detection method is crucial.Methods This study introduces RSDCNet, an enhanced lightweight neural network architecture designed for the automatic detection of benign and malignant breast cancer pathology. Utilizing the BreakHis dataset, which comprises 9109 microscopic images of breast tumors including various differentiation levels of benign and malignant samples, RSDCNet integrates depthwise separable convolution and SCSE modules. This integration aims to reduce model parameters while enhancing key feature extraction capabilities, thereby achieving both lightweight design and high efficiency.Results RSDCNet demonstrated superior performance across multiple evaluation metrics in the classification task. The model achieved an accuracy of 0.9903, a recall of 0.9897, an F1 score of 0.9888, and a precision of 0.9879, outperforming established deep learning models such as EfficientNet, RegNet, HRNet, and ViT. Notably, RSDCNet's parameter count stood at just 1,199,662, significantly lower than HRNet's 19,254,102 and ViT's 85,800,194, highlighting its enhanced resource efficiency.Conclusion The RSDCNet model presented in this study excels in the efficient and accurate classification of benign and malignant breast cancer pathology. Compared to traditional methods and other leading models, RSDCNet not only reduces computational resource consumption but also offers improved feature extraction and clinical interpretability. This advancement provides substantial technical support for the intelligent diagnosis of breast cancer, paving the way for more effective treatment planning and prognosis assessment. | H19: Breast cancer; pathological image; benign and malignant detection; deep learning; lightweight | J19: SAGE PUBLICATIONS LTD | K19: Article | L19: Green Submitted, gold | M19: {=IFERROR( INDEX(survey_paper_2026!$F:$F, MATCH(LOWER(TRIM(B19)), LOWER(TRIM(survey_paper_2026!$B:$B)),0) ), "New" )} -> P | N19: {=IFERROR( INDEX(survey_paper_2026!$G:$G, MATCH(LOWER(TRIM(B19)), LOWER(TRIM(survey_paper_2026!$B:$B)),0) ), "New" )} -> Y
A20: Chen, ZY; Zeng, XH; Cheng, K; Hong, Y; Liu, Y; Fang, R; Liao, CS; Plain, J | B20: a lightweight multi-scale efficient model for breast cancer detection and classification in mammograms | C20: 2025 | D20: NEURAL INFORMATION PROCESSING, ICONIP 2024, PT IV | E20: 25 | F20: Fudan University; Fudan University; Fudan University; Centre National de la Recherche Scientifique (CNRS); Universite de Technologie de Troyes | G20: Early detection and classification of breast tumors via mammographic images are critical for reducing mortality rates. We introduce a lightweight and efficient tumor detection model built on an enhanced YOLOv8 framework to support diagnosis. Firstly, we introduce a multi-scale lightweight convolution module named MSLConv. We further integrate batch normalization and the SILU activation function to create a comprehensive convolutional module called MSLCBS. To further enhance the model, we have restructured the detection head to substantially decrease the parameter count in this segment of the network. Additionally, to capture subtle features such as microcalcifications and irregular textures, we incorporate Focal Modulation to improve feature fusion capabilities. This approach aggregates and interacts with contextual information in a lightweight manner. Considering the diversity in the shape, texture, and size of breast tumors, we introduce WISE-IOU, a bounding box regression scheme to enhance the model's generalization capability. All of the extensive experiments on CBIS-DDSM and INBREAST datasets have proven that our method achieves the highest mAP50 score with the fewest parameters and computational load, which validate its reliability. | H20: Mammograms; Breast cancer; Mass detection; Computer aided detection | J20: SPRINGER-VERLAG SINGAPORE PTE LTD | K20: Proceedings Paper | M20: {=IFERROR( INDEX(survey_paper_2026!$F:$F, MATCH(LOWER(TRIM(B20)), LOWER(TRIM(survey_paper_2026!$B:$B)),0) ), "New" )} -> P | N20: {=IFERROR( INDEX(survey_paper_2026!$G:$G, MATCH(LOWER(TRIM(B20)), LOWER(TRIM(survey_paper_2026!$B:$B)),0) ), "New" )} -> Y
A21: Maisen, C; Auephanwiriyakul, S; Theera-Umpon, N | B21: a novel learning vector quantization inference classifier | C21: 2017 | D21: INTELLIGENT INFORMATION AND DATABASE SYSTEMS, ACIIDS 2017, PT I | E21: 35 | F21: Chiang Mai University; Chiang Mai University; Chiang Mai University; Chiang Mai University | G21: One of the popular tools in pattern recognition is a neuro-fuzzy system. Most of the neuro-fuzzy systems are based on a multi-layer perceptrons. In this paper, we incorporate learning vector quantization in a neuro-fuzzy system. The prototype update equation is based on the learning vector quantization while the gradient descent technique is used in the weight update equation. Since weights contain informative information, they are exploited to select a good feature set. There are 8 data sets used in the experiment, i.e., Iris Plants, Wisconsin Breast Cancer (WBC), Pima Indians Diabetes, Wine, Ionosphere, Colon Tumor, Diffuse Large B-Cell Lymphoma (DLBCL), and Glioma Tumor (GLI_85). The results show that our algorithm provides good classification rates on all data sets. It is able to select a good feature set with a small number of features. We compare our results indirectly with the existing algorithms as well. The comparison result shows that our algorithm performs better than those existing ones. | H21: Neuro-fuzzy classifier; Learning vector quantization; Prototype-based rule; Rule extraction; Feature selection | I21: FEATURE-SELECTION; FUZZY; SYSTEMS | J21: SPRINGER INTERNATIONAL PUBLISHING AG | K21: Proceedings Paper | M21: SA | N21: {=IFERROR( INDEX(survey_paper_2026!$G:$G, MATCH(LOWER(TRIM(B21)), LOWER(TRIM(survey_paper_2026!$B:$B)),0) ), "New" )} -> New
A22: Raiaan, MAK; Fahad, NM; Mukta, MSH; Shatabda, S | B22: mammo-light: a lightweight convolutional neural network for diagnosing breast cancer from mammography images | C22: 2024 | D22: BIOMEDICAL SIGNAL PROCESSING AND CONTROL | E22: 67 | F22: United International University (UIU); Lappeenranta-Lahti University of Technology LUT | G22: People of all countries, developed and developing alike endure cancer-related fatal diseases. The rate of breast cancer in females is increasing daily, partly due to ignorance and misdiagnosis in the early stages. Diagnosis of breast cancer accurately during its earlier stages of development can result in proper initial treatment for breast cancer. Artificial intelligence can aid in the acceleration and automation of breast cancer detection. Deep learning is decisive in effectively recognizing and classifying cancer on large datasets of medical images. In this paper, we propose a novel computer-aided classification approach, Mammo-Light for breast cancer prediction. Preprocessing strategies have been utilized to eradicate the noise and enhance mammogram lesions. Photometric augmentation techniques adapted to the preprocessed classes to balance and increase the size of the dataset. After that, a lightweight yet intuitive convolutional neural network is applied to classify breast cancer on the publicly available dataset CBIS-DDSM. For further validation of the proposed approach, we have used the MIAS dataset. Mammo-Light attained a 99.17% and 98.42% test accuracy respectively for CBISDDSM and MIAS datasets and outperformed state-of-the-art methods in terms of accuracy and other metrics. Due to being the lightweight model, Mammo-Light performs exceptionally well with fewer parameters and computational time, which can potentially contribute to the field of breast cancer early diagnosis and enable fast treatment. | H22: Mammograms; Image preprocessing; Breast cancer classification; Data augmentation; Lightweight CNN; Transfer learning models | I22: CLASSIFICATION; SEGMENTATION; SYSTEM; MODEL; CNN | J22: ELSEVIER SCI LTD | K22: Article | M22: {=IFERROR( INDEX(survey_paper_2026!$F:$F, MATCH(LOWER(TRIM(B22)), LOWER(TRIM(survey_paper_2026!$B:$B)),0) ), "New" )} -> P | N22: {=IFERROR( INDEX(survey_paper_2026!$G:$G, MATCH(LOWER(TRIM(B22)), LOWER(TRIM(survey_paper_2026!$B:$B)),0) ), "New" )} -> Y
A23: Choudhary, T; Mishra, V; Goswami, A; Sarangapani, J | B23: a transfer learning with structured filter pruning approach for improved breast cancer classification on point-of-care devices | C23: 2021 | D23: COMPUTERS IN BIOLOGY AND MEDICINE | E23: 58 | F23: University of Missouri System; Missouri University of Science & Technology | G23: Background and objective: A significant progress has been made in automated medical diagnosis with the advent of deep learning methods in recent years. However, deploying a deep learning model for mobile and small-scale, low-cost devices is a major bottleneck. Further, breast cancer is more prevalent currently, and ductal carcinoma being its most common type. Although many machine/deep learning methods have already been investigated, still, there is a need for further improvement. Method: This paper proposes a novel deep convolutional neural network (CNN) based transfer learning approach complemented with structured filter pruning for histopathological image classification, and to bring down the run-time resource requirement of the trained deep learning models. In the proposed method, first, the less important filters are pruned from the convolutional layers and then the pruned models are trained on the histopathological image dataset. Results: We performed extensive experiments using three popular pre-trained CNNs, VGG19, ResNet34, and ResNet50. With VGG19 pruned model, we achieved an accuracy of 91.25% outperforming earlier methods on the same dataset and architecture while reducing 63.46% FLOPs. Whereas, with the ResNet34 pruned model, the accuracy increases to 91.80% with 40.63% fewer FLOPs. Moreover, with the ResNet50 model, we achieved an accuracy of 92.07% with 30.97% less FLOPs. Conclusion: The experimental results reveal that the pre-trained model's performance complemented with filter pruning exceeds original pre-trained models. Another important outcome of the research is that the pruned model with reduced resource requirements can be deployed in point-of-care devices for automated diagnosis applications with ease. | H23: Breast cancer; Invasive ductal carcinoma; Efficient inference; Convolutional neural network; Filter pruning | I23: IMAGE CLASSIFICATION; NEURAL-NETWORK | J23: PERGAMON-ELSEVIER SCIENCE LTD | K23: Article | M23: P | N23: Y
A24: Yan, CX; Zeng, XY; Xi, R; Ahmed, A; Hou, MS; Tunio, MH | B24: pla-a privacy-embedded lightweight and efficient automated breast cancer accurate diagnosis framework for the internet of medical things | C24: 2023 | D24: ELECTRONICS | E24: 55 | F24: University of Electronic Science & Technology of China; Chengdu Technological University | G24: The Internet of Medical Things (IoMT) can automate breast tumor detection and classification with the potential of artificial intelligence. However, the leakage of sensitive data can cause harm to patients. To address this issue, this study proposed an intrauterine breast cancer diagnosis method, namely Privacy-Embedded Lightweight and Efficient Automated (PLA), for IoMT, which represents an approach that combines privacy-preserving techniques, efficiency, and automation to achieve our goals. Firstly, our model is designed to achieve lightweight classification prediction and global information processing of breast cancer by utilizing an advanced IoMT-friendly ViT backbone. Secondly, PLA protects patients' privacy by federated learning, taking the classification task of breast cancer as the main task and introducing the texture analysis task of breast cancer images as the auxiliary task to train the model. For our PLA framework, the classification accuracy is 0.953, the recall rate is 0.998 for the best, the F1 value is 0.969, the precision value is 0.988, and the classification time is 61.9 ms. The experimental results show that the PLA model performs better than all of the comparison methods in terms of accuracy, with an improvement of more than 0.5%. Furthermore, our proposed model demonstrates significant advantages over the comparison methods regarding time and memory. | H24: PLA; privacy-embedded; federated learning; breast cancer classification; Internet of Medical Things; lightweight | I24: DEEP; CLASSIFICATION | J24: MDPI | K24: Article | L24: gold | M24: P | N24: Y
A25: Oliveira, HS; Teixeira, JF; Oliveira, HP | B25: lightweight deep learning pipeline for detection, segmentation and classification of breast cancer anomalies | C25: 2019 | D25: IMAGE ANALYSIS AND PROCESSING - ICIAP 2019, PT II | E25: 11 | F25: Universidade do Porto; Universidade do Porto; INESC TEC | G25: The small amount of public available medical images hinders the use of deep learning techniques for mammogram automatic diagnosis. Deep learning methods require large annotated training sets to be effective, however medical datasets are costly to obtain and suffer from large variability. In this work, a lightweight deep learning pipeline to detect, segment and classify anomalies in mammogram images is presented. First, data augmentation using the ground-truth annotation is performed and used by a cascade segmentation and classification methods. Results are obtained using the INbreast public database in the context of lesion detection and BI-RADS classification. Moreover, a pre-trained Convolutional Neural Network using ResNet50 is modified to generate the lesion regions proposals followed by a false positive reduction and contour refinement stages while a pre-trained VGG16 network is fine-tuned to classify mammograms. The detection and segmentation stage results show that the cascade configuration achieves a DICE of 0.83 without massive training while the multi-class classification exhibits an MAE of 0.58 with data augmentation. | H25: Lesion detection; Segmentation; Classification; Deep learning | I25: MASSES | J25: SPRINGER INTERNATIONAL PUBLISHING AG | K25: Proceedings Paper | M25: {=IFERROR( INDEX(survey_paper_2026!$F:$F, MATCH(LOWER(TRIM(B25)), LOWER(TRIM(survey_paper_2026!$B:$B)),0) ), "New" )} -> P | N25: {=IFERROR( INDEX(survey_paper_2026!$G:$G, MATCH(LOWER(TRIM(B25)), LOWER(TRIM(survey_paper_2026!$B:$B)),0) ), "New" )} -> Y
A26: Zhu, C; Song, FZ; Wang, Y; Dong, HH; Guo, Y; Liu, J | B26: breast cancer histopathology image classification through assembling multiple compact cnns | C26: 2019 | D26: BMC MEDICAL INFORMATICS AND DECISION MAKING | E26: 37 | F26: Beijing University of Posts & Telecommunications; Capital Medical University | G26: Background Breast cancer causes hundreds of thousands of deaths each year worldwide. The early stage diagnosis and treatment can significantly reduce the mortality rate. However, the traditional manual diagnosis needs intense workload, and diagnostic errors are prone to happen with the prolonged work of pathologists. Automatic histopathology image recognition plays a key role in speeding up diagnosis and improving the quality of diagnosis. Methods In this work, we propose a breast cancer histopathology image classification by assembling multiple compact Convolutional Neural Networks (CNNs). First, a hybrid CNN architecture is designed, which contains a global model branch and a local model branch. By local voting and two-branch information merging, our hybrid model obtains stronger representation ability. Second, by embedding the proposed Squeeze-Excitation-Pruning (SEP) block into our hybrid model, the channel importance can be learned and the redundant channels are thus removed. The proposed channel pruning scheme can decrease the risk of overfitting and produce higher accuracy with the same model size. At last, with different data partition and composition, we build multiple models and assemble them together to further enhance the model generalization ability. Results Experimental results show that in public BreaKHis dataset, our proposed hybrid model achieves comparable performance with the state-of-the-art. By adopting the multi-model assembling scheme, our method outperforms the state-of-the-art in both patient level and image level accuracy for BACH dataset. Conclusions We propose a novel compact breast cancer histopathology image classification scheme by assembling multiple compact hybrid CNNs. The proposed scheme achieves promising results for the breast cancer image classification task. Our method can be used in breast cancer auxiliary diagnostic scenario, and it can reduce the workload of pathologists as well as improve the quality of diagnosis. | H26: Breast cancer; Channel pruning; Histopathology; Hybrid CNN | I26: DIAGNOSIS | J26: BMC | K26: Article | L26: Green Submitted, gold | M26: P | N26: Y
A27: Chi, TN; Thu, HL; Quang, TD; Taniar, D | B27: a lightweight method for breast cancer detection using thermography images with optimized cnn feature and efficient classification | C27: 2025 | D27: JOURNAL OF IMAGING INFORMATICS IN MEDICINE | E27: 41 | F27: Vietnam Academy of Science & Technology (VAST); Monash University; FPT University | G27: Breast cancer is a prominent cause of death among women worldwide. Infrared thermography, due to its cost-effectiveness and non-ionizing radiation, has emerged as a promising tool for early breast cancer diagnosis. This article presents a hybrid model approach for breast cancer detection using thermography images, designed to process and classify these images into healthy or cancerous categories, thus supporting disease diagnosis. Multiple pre-trained convolutional neural networks are employed for image feature extraction, and feature filter methods are proposed for feature selection, with diverse classifiers utilized for image classification. Evaluating the DRM-IR test set revealed that the combination of ResNet34, Chi-square (chi 2\documentclass[12pt]{minimal} \usepackage{amsmath} \usepackage{wasysym} \usepackage{amsfonts} \usepackage{amssymb} \usepackage{amsbsy} \usepackage{mathrsfs} \usepackage{upgreek} \setlength{\oddsidemargin}{-69pt} \begin{document}$$\varvec{\chi }<^>{\varvec{2}}$$\end{document}) filter, and SVM classifier demonstrated superior performance, achieving the highest accuracy at 99.62%\documentclass[12pt]{minimal} \usepackage{amsmath} \usepackage{wasysym} \usepackage{amsfonts} \usepackage{amssymb} \usepackage{amsbsy} \usepackage{mathrsfs} \usepackage{upgreek} \setlength{\oddsidemargin}{-69pt} \begin{document}$$\varvec{99.62\%}$$\end{document}. Furthermore, the highest accuracy improvement obtained was 18.3%\documentclass[12pt]{minimal} \usepackage{amsmath} \usepackage{wasysym} \usepackage{amsfonts} \usepackage{amssymb} \usepackage{amsbsy} \usepackage{mathrsfs} \usepackage{upgreek} \setlength{\oddsidemargin}{-69pt} \begin{document}$$\varvec{18.3\%}$$\end{document} when using the SVM classifier and Chi-square filter compared to regular convolutional neural networks. The results confirmed that the proposed method, with its high accuracy and lightweight model, outperforms state-of-the-art breast cancer detection from thermography image methods, making it a good choice for computer-aided diagnosis. | H27: Breast cancer; Breast thermal image; CNN feature exactor; Feature optimization; Classifiers | J27: SPRINGER | K27: Article | L27: Green Accepted | M27: {=IFERROR( INDEX(survey_paper_2026!$F:$F, MATCH(LOWER(TRIM(B27)), LOWER(TRIM(survey_paper_2026!$B:$B)),0) ), "New" )} -> P | N27: {=IFERROR( INDEX(survey_paper_2026!$G:$G, MATCH(LOWER(TRIM(B27)), LOWER(TRIM(survey_paper_2026!$B:$B)),0) ), "New" )} -> Y
A28: Agrawal, K; Borthakur, A; Singh, AK; Srikaran, P; Nandi, D; Pujari, O | B28: neural decision tree for bio-tinyml | C28: 2024 | D28: 2024 IEEE BIOMEDICAL CIRCUITS AND SYSTEMS CONFERENCE, BIOCAS 2024 | E28: 14 | F28: Indian Institute of Technology System (IIT System); Indian Institute of Technology (IIT) - Guwahati; Indian Institute of Technology System (IIT System); Indian Institute of Technology (IIT) - Hyderabad | G28: Deep neural networks(NN) are widely popular candidates for introducing machine learning in resource-constrained devices(tinyML). However, NNs in tinyML applications come with constraints such as high memory footprint and power consumption. Another popular candidate is decision trees (DT), which are lightweight, but in DT - choosing the tree depth, the best feature, and the threshold for subsetting data is not end-to-end as in parameter tuning of NNs. Hence, we here design a Neural Decision Tree (NDT), which can be trained using backpropagation in an end-to-end fashion and is simultaneously lightweight. We evaluate NDT for potential healthcare applications in Epileptic Seizure, Cervical Cancer, Breast Cancer, Parkinson's, and Heart Disease Detection. Careful studies reveal that NDT performs at par with NNs but is computationally simpler with fewer neurons and with a hugely reduced number of multiply-accumulate operations(MACs). In addition, we propose methods for interpreting NDT behavior. Moreover, we perform systematic ablation studies on NDT to justify the design choices. | H28: tinyML; Low power; Deep Learning; Decision Tree; Healthcare | J28: IEEE | K28: Proceedings Paper | M28: SA
